<?xml version="1.0" encoding="utf-8"?>
<!-- =================================================================================== -->
<!-- |    This document was autogenerated by xacro from robot.xacro                    | -->
<!-- |    EDITING THIS FILE BY HAND IS NOT RECOMMENDED                                 | -->
<!-- =================================================================================== -->
<robot name="a1">
  <!-- dynamics inertial value -->
  <!-- trunk -->
  <!-- <xacro:property name="trunk_mass" value="5.660"/>
    <xacro:property name="trunk_com_x" value="0.012731"/>
    <xacro:property name="trunk_com_y" value="0.002186"/>
    <xacro:property name="trunk_com_z" value="0.000515"/>
    <xacro:property name="trunk_ixx" value="0.016839930"/>
    <xacro:property name="trunk_ixy" value="0.000083902"/>
    <xacro:property name="trunk_ixz" value="0.000597679"/>
    <xacro:property name="trunk_iyy" value="0.056579028"/>
    <xacro:property name="trunk_iyz" value="0.000025134"/>
    <xacro:property name="trunk_izz" value="0.064713601"/> -->
  <material name="black">
    <color rgba="0.0 0.0 0.0 1.0"/>
  </material>
  <material name="blue">
    <color rgba="0.0 0.0 0.8 1.0"/>
  </material>
  <material name="green">
    <color rgba="0.0 0.8 0.0 1.0"/>
  </material>
  <material name="grey">
    <color rgba="0.2 0.2 0.2 1.0"/>
  </material>
  <material name="silver">
    <color rgba="0.913725490196 0.913725490196 0.847058823529 1.0"/>
  </material>
  <material name="orange">
    <color rgba="1.0 0.423529411765 0.0392156862745 1.0"/>
  </material>
  <material name="brown">
    <color rgba="0.870588235294 0.811764705882 0.764705882353 1.0"/>
  </material>
  <material name="red">
    <color rgba="0.8 0.0 0.0 1.0"/>
  </material>
  <material name="dark_grey">
    <color rgba="0.2 0.2 0.2 1.0" />
    </material>
  <material name="self">
    <!-- <color rgba="0.5019607843137255 0.38823529411764707 0.43137254901960786 1.0"/>
     -->
     <color rgba="0.5647058823529412 0.5803921568627451 0.5764705882352941 1.0"/>
     
</material>

  <material name="white">
    <color rgba="1.0 1.0 1.0 1.0"/>
  </material>
  <!-- <xacro:include filename="$(find a1_gazebo)/launch/stairs.urdf.xacro"/> -->
  <!-- <xacro:stairs stairs="15" xpos="0" ypos="0" zpos="0" /> -->
  <!-- Debug mode will hung up the robot, use "true" or "false" to switch it. -->
  <!-- <xacro:if value="$(arg DEBUG)">
        <link name="world"/>
        <joint name="base_static_joint" type="fixed">
            <origin rpy="0 0 0" xyz="0 0 0"/>
            <parent link="world"/>
            <child link="base"/>
        </joint>
    </xacro:if>  -->
  <link name="base">
    <visual>
      <origin rpy="1.57079632 0 0" xyz="0 0 0"/>
      <geometry>
        <box size="0.001 0.001 0.001"/>
      </geometry>
    </visual>
  </link>
  <joint name="floating_base" type="fixed" dont_collapse="true">
    <origin rpy="0 0 0" xyz="0 0 0"/>
    <parent link="base"/>
    <child link="trunk"/>
  </joint>
  <link name="trunk">
    <visual>
      <origin rpy="1.57079632 0 0" xyz="0 0 0"/>
      <geometry>
        <mesh filename="../meshes/trunk.dae" scale="1 1 1"/>
      </geometry>
      <material name="self"/>
    </visual>
    <collision>
      <origin rpy="1.57079632 0 0" xyz="0 0 0"/>
      <geometry>
        <!-- <box size="0.267 0.194 0.114"/> -->
        <mesh filename="../meshes/trunk.dae" scale="1 1 1"/>
      </geometry>
    </collision>
    <inertial>
      <origin rpy="1.57079632 0 0" xyz="0.0 0.0041 -0.0005"/>
      <mass value="6.0"/>
      <inertia ixx="0.0158533" ixy="-3.66e-05" ixz="-6.11e-05" iyy="0.0377999" iyz="-2.75e-05" izz="0.0456542"/>
    </inertial>
  </link>
  <joint name="imu_joint" type="fixed">
    <parent link="trunk"/>
    <child link="imu_link"/>
    <origin rpy="0 0 0" xyz="0 0 0"/>
  </joint>
  <link name="imu_link">
    <inertial>
      <mass value="0.001"/>
      <origin rpy="1.57079632 0 0" xyz="0 0 0"/>
      <inertia ixx="0.0001" ixy="0" ixz="0" iyy="0.0001" iyz="0" izz="0.0001"/>
    </inertial>
    <visual>
      <origin rpy="1.57079632 0 0" xyz="0 0 0"/>
      <geometry>
        <box size="0.001 0.001 0.001"/>
      </geometry>
      <material name="red"/>
    </visual>
    <collision>
      <origin rpy="1.57079632 0 0" xyz="0 0 0"/>
      <geometry>
        <box size=".001 .001 .001"/>
      </geometry>
    </collision>
  </link>
  <joint name="FR_hip_joint" type="revolute">
    <origin rpy="0 0 0" xyz="0.1805 -0.047 0"/>
    <parent link="trunk"/>
    <child link="FR_hip"/>
    <axis xyz="1 0 0"/>
    <dynamics damping="0.01" friction="0.2"/>
    <limit effort="33.5" lower="-0.802851455917" upper="0.802851455917" velocity="21"/>
  </joint>
  <link name="FR_hip">
    <visual>
      <origin rpy="4.712388 0 0" xyz="0 0 0"/>
      <geometry>
        <mesh filename="../meshes/hip.dae" scale="1 1 1"/>
      </geometry>
      <material name="self"/>
    </visual>
    <!-- <collision>
      <origin rpy="3.141592 0 0" xyz="0 0 0"/>
      <geometry>
        <cylinder length="0.04" radius="0.046"/>
      </geometry>
    </collision> -->
    <inertial>
      <origin rpy="1.57079632 0 0" xyz="-0.003311 -0.000635 3.1e-05"/>
      <mass value="0.696"/>
      <inertia ixx="0.000469246" ixy="9.409e-06" ixz="-3.42e-07" iyy="0.00080749" iyz="4.66e-07" izz="0.000552929"/>
    </inertial>
  </link>
  <joint name="FR_hip_fixed" type="fixed">
    <origin rpy="0 0 0" xyz="0 -0.081 0"/>
    <parent link="FR_hip"/>
    <child link="FR_thigh_shoulder"/>
  </joint>
  <!-- this link is only for collision -->
  <link name="FR_thigh_shoulder">
    <!-- <collision>
      <origin rpy="3.141592 0 0" xyz="0 0 0"/>
      <geometry>
        <cylinder length="0.032" radius="0.041"/>
      </geometry>
    </collision> -->
  </link>
  <joint name="FR_thigh_joint" type="revolute">
    <origin rpy="0 0 0" xyz="0 -0.0838 0"/>
    <parent link="FR_hip"/>
    <child link="FR_thigh"/>
    <axis xyz="0 1 0"/>
    <dynamics damping="0.01" friction="0.2"/>
    <limit effort="33.5" lower="-1.0471975512" upper="4.18879020479" velocity="21"/>
  </joint>
  <link name="FR_thigh">
    <visual>
      <origin rpy="1.57079632 0 0" xyz="0 0 0"/>
      <geometry>
        <mesh filename="../meshes/thigh_mirror.dae" scale="1 1 1"/>
      </geometry>
      <material name="self"/>
    </visual>
    <collision>
      <origin rpy="1.57079632 1.57079632679 0" xyz="0 0 -0.1"/>
      <geometry>
        <box size="0.2 0.0245 0.034"/>
      </geometry>
    </collision>
    <inertial>
      <origin rpy="1.57079632 0 0" xyz="-0.003237 0.022327 -0.027326"/>
      <mass value="1.013"/>
      <inertia ixx="0.005529065" ixy="-4.825e-06" ixz="0.000343869" iyy="0.005139339" iyz="-2.2448e-05" izz="0.001367788"/>
    </inertial>
  </link>
  <joint name="FR_calf_joint" type="revolute">
    <origin rpy="0 0 0" xyz="0 0 -0.2"/>
    <parent link="FR_thigh"/>
    <child link="FR_calf"/>
    <axis xyz="0 1 0"/>
    <dynamics damping="0.01" friction="0.2"/>
    <limit effort="33.5" lower="-2.69653369433" upper="-0.916297857297" velocity="21"/>
  </joint>
  <link name="FR_calf">
    <visual>
      <origin rpy="1.57079632 0 0" xyz="0 0 0"/>
      <geometry>
        <mesh filename="../meshes/calf.dae" scale="1 1 1"/>
      </geometry>
      <material name="self"/>
    </visual>
    <collision>
      <origin rpy="1.57079632 1.57079632679 0" xyz="0 0 -0.1"/>
      <geometry>
        <box size="0.2 0.016 0.016"/>
      </geometry>
    </collision>
    <inertial>
      <origin rpy="1.57079632 0 0" xyz="0.006435 0.0 -0.107388"/>
      <mass value="0.166"/>
      <inertia ixx="0.002997972" ixy="0.0" ixz="-0.000141163" iyy="0.003014022" iyz="0.0" izz="3.2426e-05"/>
    </inertial>
  </link>
  <joint name="FR_foot_fixed" type="fixed" dont_collapse="true">
    <origin rpy="0 0 0" xyz="0 0 -0.2"/>
    <parent link="FR_calf"/>
    <child link="FR_foot"/>
  </joint>
  <link name="FR_foot">
    <visual>
      <origin rpy="1.57079632 0 0" xyz="0 0 0"/>
      <geometry>
        <sphere radius="0.01"/>
      </geometry>
      <material name="self"/>
    </visual>
    <collision>
      <origin rpy="1.57079632 0 0" xyz="0 0 0"/>
      <geometry>
        <sphere radius="0.02"/>
      </geometry>
    </collision>
    <inertial>
      <mass value="0.06"/>
      <inertia ixx="9.6e-06" ixy="0.0" ixz="0.0" iyy="9.6e-06" iyz="0.0" izz="9.6e-06"/>
    </inertial>
  </link>
 
  <joint name="FL_hip_joint" type="revolute">
    <origin rpy="0 0 0" xyz="0.1805 0.047 0"/>
    <parent link="trunk"/>
    <child link="FL_hip"/>
    <axis xyz="1 0 0"/>
    <dynamics damping="0.01" friction="0.2"/>
    <limit effort="33.5" lower="-0.802851455917" upper="0.802851455917" velocity="21"/>
  </joint>
  <link name="FL_hip">
    <visual>
      <origin rpy="1.57079632 0 0" xyz="0 0 0"/>
      <geometry>
        <mesh filename="../meshes/hip.dae" scale="1 1 1"/>
      </geometry>
      <material name="self"/>
    </visual>
    <!-- <collision>
      <origin rpy="3.141592 0 0" xyz="0 0 0"/>
      <geometry>
        <cylinder length="0.04" radius="0.046"/>
      </geometry>
    </collision> -->
    <inertial>
      <origin rpy="1.57079632 0 0" xyz="-0.003311 0.000635 3.1e-05"/>
      <mass value="0.696"/>
      <inertia ixx="0.000469246" ixy="-9.409e-06" ixz="-3.42e-07" iyy="0.00080749" iyz="-4.66e-07" izz="0.000552929"/>
    </inertial>
  </link>
  <joint name="FL_hip_fixed" type="fixed">
    <origin rpy="0 0 0" xyz="0 0.081 0"/>
    <parent link="FL_hip"/>
    <child link="FL_thigh_shoulder"/>
  </joint>
  <!-- this link is only for collision -->
  <link name="FL_thigh_shoulder">
    <!-- <collision>
      <origin rpy="3.141592 0 0" xyz="0 0 0"/>
      <geometry>
        <cylinder length="0.032" radius="0.041"/>
      </geometry>
    </collision> -->
  </link>
  <joint name="FL_thigh_joint" type="revolute">
    <origin rpy="0 0 0" xyz="0 0.0838 0"/>
    <parent link="FL_hip"/>
    <child link="FL_thigh"/>
    <axis xyz="0 1 0"/>
    <dynamics damping="0.01" friction="0.2"/>
    <limit effort="33.5" lower="-1.0471975512" upper="4.18879020479" velocity="21"/>
  </joint>
  <link name="FL_thigh">
    <visual>
      <origin rpy="1.57079632 0 0" xyz="0 0 0"/>
      <geometry>
        <mesh filename="../meshes/thigh.dae" scale="1 1 1"/>
      </geometry>
      <material name="self"/>
    </visual>
    <collision>
      <origin rpy="1.57079632 1.57079632679 0" xyz="0 0 -0.1"/>
      <geometry>
        <box size="0.2 0.0245 0.034"/>
      </geometry>
    </collision>
    <inertial>
      <origin rpy="1.57079632 0 0" xyz="-0.003237 -0.022327 -0.027326"/>
      <mass value="1.013"/>
      <inertia ixx="0.005529065" ixy="4.825e-06" ixz="0.000343869" iyy="0.005139339" iyz="2.2448e-05" izz="0.001367788"/>
    </inertial>
  </link>
  <joint name="FL_calf_joint" type="revolute">
    <origin rpy="0 0 0" xyz="0 0 -0.2"/>
    <parent link="FL_thigh"/>
    <child link="FL_calf"/>
    <axis xyz="0 1 0"/>
    <dynamics damping="0.01" friction="0.2"/>
    <limit effort="33.5" lower="-2.69653369433" upper="-0.916297857297" velocity="21"/>
  </joint>
  <link name="FL_calf">
    <visual>
      <origin rpy="1.57079632 0 0" xyz="0 0 0"/>
      <geometry>
        <mesh filename="../meshes/calf.dae" scale="1 1 1"/>
      </geometry>
      <material name="self"/>
    </visual>
    <collision>
      <origin rpy="1.57079632 1.57079632679 0" xyz="0 0 -0.1"/>
      <geometry>
        <box size="0.2 0.016 0.016"/>
      </geometry>
    </collision>
    <inertial>
      <origin rpy="1.57079632 0 0" xyz="0.006435 0.0 -0.107388"/>
      <mass value="0.166"/>
      <inertia ixx="0.002997972" ixy="0.0" ixz="-0.000141163" iyy="0.003014022" iyz="0.0" izz="3.2426e-05"/>
    </inertial>
  </link>
  <joint name="FL_foot_fixed" type="fixed" dont_collapse="true">
    <origin rpy="0 0 0" xyz="0 0 -0.2"/>
    <parent link="FL_calf"/>
    <child link="FL_foot"/>
  </joint>
  <link name="FL_foot">
    <visual>
      <origin rpy="1.57079632 0 0" xyz="0 0 0"/>
      <geometry>
        <sphere radius="0.01"/>
      </geometry>
      <material name="self"/>
    </visual>
    <collision>
      <origin rpy="1.57079632 0 0" xyz="0 0 0"/>
      <geometry>
        <sphere radius="0.02"/>
      </geometry>
    </collision>
    <inertial>
      <mass value="0.06"/>
      <inertia ixx="9.6e-06" ixy="0.0" ixz="0.0" iyy="9.6e-06" iyz="0.0" izz="9.6e-06"/>
    </inertial>
  </link>
  
  <joint name="RR_hip_joint" type="revolute">
    <origin rpy="0 0 0" xyz="-0.1805 -0.047 0"/>
    <parent link="trunk"/>
    <child link="RR_hip"/>
    <axis xyz="1 0 0"/>
    <dynamics damping="0.01" friction="0.2"/>
    <limit effort="33.5" lower="-0.802851455917" upper="0.802851455917" velocity="21"/>
  </joint>
  <link name="RR_hip">
    <visual>
      <origin rpy="4.712388 3.14159265359 0" xyz="0 0 0"/>
      <geometry>
        <mesh filename="../meshes/hip.dae" scale="1 1 1"/>
      </geometry>
      <material name="self"/>
    </visual>
    <!-- <collision>
      <origin rpy="3.141592 0 0" xyz="0 0 0"/>
      <geometry>
        <cylinder length="0.04" radius="0.046"/>
      </geometry>
    </collision> -->
    <inertial>
      <origin rpy="1.57079632 0 0" xyz="0.003311 -0.000635 3.1e-05"/>
      <mass value="0.696"/>
      <inertia ixx="0.000469246" ixy="-9.409e-06" ixz="3.42e-07" iyy="0.00080749" iyz="4.66e-07" izz="0.000552929"/>
    </inertial>
  </link>
  <joint name="RR_hip_fixed" type="fixed">
    <origin rpy="0 0 0" xyz="0 -0.081 0"/>
    <parent link="RR_hip"/>
    <child link="RR_thigh_shoulder"/>
  </joint>
  <!-- this link is only for collision -->
  <link name="RR_thigh_shoulder">
    <!-- <collision>
      <origin rpy="3.141592 0 0" xyz="0 0 0"/>
      <geometry>
        <cylinder length="0.032" radius="0.041"/>
      </geometry>
    </collision> -->
  </link>
  <joint name="RR_thigh_joint" type="revolute">
    <origin rpy="0 0 0" xyz="0 -0.0838 0"/>
    <parent link="RR_hip"/>
    <child link="RR_thigh"/>
    <axis xyz="0 1 0"/>
    <dynamics damping="0.01" friction="0.2"/>
    <limit effort="33.5" lower="-1.0471975512" upper="4.18879020479" velocity="21"/>
  </joint>
  <link name="RR_thigh">
    <visual>
      <origin rpy="1.57079632 0 0" xyz="0 0 0"/>
      <geometry>
        <mesh filename="../meshes/thigh_mirror.dae" scale="1 1 1"/>
      </geometry>
      <material name="self"/>
    </visual>
    <collision>
      <origin rpy="1.57079632 1.57079632679 0" xyz="0 0 -0.1"/>
      <geometry>
        <box size="0.2 0.0245 0.034"/>
      </geometry>
    </collision>
    <inertial>
      <origin rpy="1.57079632 0 0" xyz="-0.003237 0.022327 -0.027326"/>
      <mass value="1.013"/>
      <inertia ixx="0.005529065" ixy="-4.825e-06" ixz="0.000343869" iyy="0.005139339" iyz="-2.2448e-05" izz="0.001367788"/>
    </inertial>
  </link>
  <joint name="RR_calf_joint" type="revolute">
    <origin rpy="0 0 0" xyz="0 0 -0.2"/>
    <parent link="RR_thigh"/>
    <child link="RR_calf"/>
    <axis xyz="0 1 0"/>
    <dynamics damping="0.01" friction="0.2"/>
    <limit effort="33.5" lower="-2.69653369433" upper="-0.916297857297" velocity="21"/>
  </joint>
  <link name="RR_calf">
    <visual>
      <origin rpy="1.57079632 0 0" xyz="0 0 0"/>
      <geometry>
        <mesh filename="../meshes/calf.dae" scale="1 1 1"/>
      </geometry>
      <material name="self"/>
    </visual>
    <collision>
      <origin rpy="1.57079632 1.57079632679 0" xyz="0 0 -0.1"/>
      <geometry>
        <box size="0.2 0.016 0.016"/>
      </geometry>
    </collision>
    <inertial>
      <origin rpy="1.57079632 0 0" xyz="0.006435 0.0 -0.107388"/>
      <mass value="0.166"/>
      <inertia ixx="0.002997972" ixy="0.0" ixz="-0.000141163" iyy="0.003014022" iyz="0.0" izz="3.2426e-05"/>
    </inertial>
  </link>
  <joint name="RR_foot_fixed" type="fixed" dont_collapse="true">
    <origin rpy="0 0 0" xyz="0 0 -0.2"/>
    <parent link="RR_calf"/>
    <child link="RR_foot"/>
  </joint>
  <link name="RR_foot">
    <visual>
      <origin rpy="1.57079632 0 0" xyz="0 0 0"/>
      <geometry>
        <sphere radius="0.01"/>
      </geometry>
      <material name="self"/>
    </visual>
    <collision>
      <origin rpy="1.57079632 0 0" xyz="0 0 0"/>
      <geometry>
        <sphere radius="0.02"/>
      </geometry>
    </collision>
    <inertial>
      <mass value="0.06"/>
      <inertia ixx="9.6e-06" ixy="0.0" ixz="0.0" iyy="9.6e-06" iyz="0.0" izz="9.6e-06"/>
    </inertial>
  </link>
  
  <joint name="RL_hip_joint" type="revolute">
    <origin rpy="0 0 0" xyz="-0.1805 0.047 0"/>
    <parent link="trunk"/>
    <child link="RL_hip"/>
    <axis xyz="1 0 0"/>
    <dynamics damping="0.01" friction="0.2"/>
    <limit effort="33.5" lower="-0.802851455917" upper="0.802851455917" velocity="21"/>
  </joint>
  <link name="RL_hip">
    <visual>
      <origin rpy="1.57079632 3.14159265359 0" xyz="0 0 0"/>
      <geometry>
        <mesh filename="../meshes/hip.dae" scale="1 1 1"/>
      </geometry>
      <material name="self"/>
    </visual>
    <!-- <collision>
      <origin rpy="3.141592 0 0" xyz="0 0 0"/>
      <geometry>
        <cylinder length="0.04" radius="0.046"/>
      </geometry>
    </collision> -->
    <inertial>
      <origin rpy="1.57079632 0 0" xyz="0.003311 0.000635 3.1e-05"/>
      <mass value="0.696"/>
      <inertia ixx="0.000469246" ixy="9.409e-06" ixz="3.42e-07" iyy="0.00080749" iyz="-4.66e-07" izz="0.000552929"/>
    </inertial>
  </link>
  <joint name="RL_hip_fixed" type="fixed">
    <origin rpy="0 0 0" xyz="0 0.081 0"/>
    <parent link="RL_hip"/>
    <child link="RL_thigh_shoulder"/>
  </joint>
  <!-- this link is only for collision -->
  <link name="RL_thigh_shoulder">
    <!-- <collision>
      <origin rpy="3.141592 0 0" xyz="0 0 0"/>
      <geometry>
        <cylinder length="0.032" radius="0.041"/>
      </geometry>
    </collision> -->
  </link>
  <joint name="RL_thigh_joint" type="revolute">
    <origin rpy="0 0 0" xyz="0 0.0838 0"/>
    <parent link="RL_hip"/>
    <child link="RL_thigh"/>
    <axis xyz="0 1 0"/>
    <dynamics damping="0.01" friction="0.2"/>
    <limit effort="33.5" lower="-1.0471975512" upper="4.18879020479" velocity="21"/>
  </joint>
  <link name="RL_thigh">
    <visual>
      <origin rpy="1.57079632 0 0" xyz="0 0 0"/>
      <geometry>
        <mesh filename="../meshes/thigh.dae" scale="1 1 1"/>
      </geometry>
      <material name="self"/>
    </visual>
    <collision>
      <origin rpy="1.57079632 1.57079632679 0" xyz="0 0 -0.1"/>
      <geometry>
        <box size="0.2 0.0245 0.034"/>
      </geometry>
    </collision>
    <inertial>
      <origin rpy="1.57079632 0 0" xyz="-0.003237 -0.022327 -0.027326"/>
      <mass value="1.013"/>
      <inertia ixx="0.005529065" ixy="4.825e-06" ixz="0.000343869" iyy="0.005139339" iyz="2.2448e-05" izz="0.001367788"/>
    </inertial>
  </link>
  <joint name="RL_calf_joint" type="revolute">
    <origin rpy="0 0 0" xyz="0 0 -0.2"/>
    <parent link="RL_thigh"/>
    <child link="RL_calf"/>
    <axis xyz="0 1 0"/>
    <dynamics damping="0.01" friction="0.2"/>
    <limit effort="33.5" lower="-2.69653369433" upper="-0.916297857297" velocity="21"/>
  </joint>
  <link name="RL_calf">
    <visual>
      <origin rpy="1.57079632 0 0" xyz="0 0 0"/>
      <geometry>
        <mesh filename="../meshes/calf.dae" scale="1 1 1"/>
      </geometry>
      <material name="self"/>
    </visual>
    <collision>
      <origin rpy="1.57079632 1.57079632679 0" xyz="0 0 -0.1"/>
      <geometry>
        <box size="0.2 0.016 0.016"/>
      </geometry>
    </collision>
    <inertial>
      <origin rpy="1.57079632 0 0" xyz="0.006435 0.0 -0.107388"/>
      <mass value="0.166"/>
      <inertia ixx="0.002997972" ixy="0.0" ixz="-0.000141163" iyy="0.003014022" iyz="0.0" izz="3.2426e-05"/>
    </inertial>
  </link>
  <joint name="RL_foot_fixed" type="fixed" dont_collapse="true">
    <origin rpy="0 0 0" xyz="0 0 -0.2"/>
    <parent link="RL_calf"/>
    <child link="RL_foot"/>
  </joint>
  <link name="RL_foot">
    <visual>
      <origin rpy="1.57079632 0 0" xyz="0 0 0"/>
      <geometry>
        <sphere radius="0.01"/>
      </geometry>
      <material name="self"/>
    </visual>
    <collision>
      <origin rpy="1.57079632 0 0" xyz="0 0 0"/>
      <geometry>
        <sphere radius="0.02"/>
      </geometry>
    </collision>
    <inertial>
      <mass value="0.06"/>
      <inertia ixx="9.6e-06" ixy="0.0" ixz="0.0" iyy="9.6e-06" iyz="0.0" izz="9.6e-06"/>
    </inertial>
  </link>
 

  <joint name="zarx5p2_mount" type="fixed">
    <origin rpy="0 0 0" xyz="0.03 0 0.057" />
    <parent link="base" />
    <child link="base_link" />
</joint>
<link name="base_link">
    <inertial>
        <origin
            xyz="-2.99718553142654E-05 3.05595229038557E-05 0.0273007719748077"
            rpy="0 0 0" />
        <mass
            value="0.440377203703276" />
        <inertia
            ixx="0.00017"
            ixy="0.00000"
            ixz="0.00000"
            iyy="0.00018"
            iyz="0.00000"
            izz="0.00016" />
    </inertial>
    <visual>
        <origin
            xyz="0 0 0"
            rpy="0 0 0" />
        <geometry>
            <mesh
                filename="../../arx5p2Go1/meshes/arx5p2_meshes/base_link.STL" />
        </geometry>
        <material
            name="dark_grey">
            <color
                rgba="0.5333333333333333 0.6078431372549019 0.7019607843137254 1.0" />
        </material>
    </visual>
    <collision>
        <origin
            xyz="0 0 0"
            rpy="0 0 0" />
        <geometry>
            <mesh
                filename="../../arx5p2Go1/meshes/arx5p2_meshes/base_link.STL" />
        </geometry>
    </collision>
</link>
<link name="zarx_body1">
    <inertial>
        <origin
            xyz="0.00593840433365978 -0.00472599953587056 0.0175081397461388"
            rpy="0 0 0" />
        <mass
            value="0.0601565264856801" />
        <inertia
            ixx="0.00007"
            ixy="0.00000"
            ixz="0.00001"
            iyy="0.00003"
            iyz="-0.00001"
            izz="0.00007" />
    </inertial>
    <visual>
        <origin
            xyz="0 0 0"
            rpy="0 0 0" />
        <geometry>
            <mesh
                filename="../../arx5p2Go1/meshes/arx5p2_meshes/link1.STL" />
        </geometry>
        <material
            name="dark_grey">
            <color
                rgba="0.5333333333333333 0.6078431372549019 0.7019607843137254 1.0" />
        </material>
    </visual>
    <collision>
        <origin
            xyz="0 0 0"
            rpy="0 0 0" />
        <geometry>
            <mesh
                filename="../../arx5p2Go1/meshes/arx5p2_meshes/link1.STL" />
        </geometry>
    </collision>
</link>
<joint name="zarx_j1"
    type="revolute">
    <origin
        xyz="0 0 0.0605"
        rpy="0 0 0" />
    <parent
        link="base_link" />
    <child
        link="zarx_body1" />
    <axis
        xyz="0 0 1" />
    <limit
        lower="-2.6179938779914944"
        upper="3.141592653589793"
        effort="15"
        velocity="3" />
</joint>
<link name="zarx_body2">
    <inertial>
        <origin
            xyz="-0.133119105376737 0.00212876404883936 0.000300078564270057"
            rpy="0 0 0" />
        <mass
            value="1.08500113729484" />
        <inertia
            ixx="0.00051"
            ixy="0.00000"
            ixz="-0.00006"
            iyy="0.01608"
            iyz="0.00000"
            izz="0.01613" />
    </inertial>
    <visual>
        <origin
            xyz="0 0 0"
            rpy="0 0 0" />
        <geometry>
            <mesh
                filename="../../arx5p2Go1/meshes/arx5p2_meshes/link2.STL" />
        </geometry>
        <material
            name="dark_grey">
            <color
                rgba="0.5333333333333333 0.6078431372549019 0.7019607843137254 1.0" />
        </material>
    </visual>
    <collision>
        <origin
            xyz="0 0 0"
            rpy="0 0 0" />
        <geometry>
            <mesh
                filename="../../arx5p2Go1/meshes/arx5p2_meshes/link2.STL" />
        </geometry>
    </collision>
</link>
<joint name="zarx_j2"
    type="revolute">
    <origin
        xyz="0.02 0 0.04"
        rpy="0 0 0" />
    <parent
        link="zarx_body1" />
    <child
        link="zarx_body2" />
    <axis
        xyz="0 1 0" />
    <limit
        lower="0"
        upper="3.6651797625214253"
        effort="15"
        velocity="3" />
</joint>
<link name="zarx_body3">
    <inertial>
        <origin
            xyz="0.187211265543004 -0.000291648902073816 -0.051519273045457"
            rpy="0 0 0" />
        <mass
            value="0.503070815258962" />
        <inertia
            ixx="0.00033"
            ixy="-0.00007"
            ixz="-0.00039"
            iyy="0.00387"
            iyz="0.00001"
            izz="0.00384" />
    </inertial>
    <visual>
        <origin
            xyz="0 0 0"
            rpy="0 0 0" />
        <geometry>
            <mesh
                filename="../../arx5p2Go1/meshes/arx5p2_meshes/link3.STL" />
        </geometry>
        <material
            name="dark_grey">
            <color
                rgba="0.5333333333333333 0.6078431372549019 0.7019607843137254 1.0" />
        </material>
    </visual>
    <collision>
        <origin
            xyz="0 0 0"
            rpy="0 0 0" />
        <geometry>
            <mesh
                filename="../../arx5p2Go1/meshes/arx5p2_meshes/link3.STL" />
        </geometry>
    </collision>
</link>
<joint name="zarx_j3"
    type="revolute">
    <origin
        xyz="-0.264 0 0"
        rpy="3.1416 0 0" />
    <parent
        link="zarx_body2" />
    <child
        link="zarx_body3" />
    <axis
        xyz="0 1 0" />
    <limit
        lower="0"
        upper="3.141582653589793"
        effort="15"
        velocity="3" />
</joint>
<link name="zarx_body4">
    <inertial>
        <origin
            xyz="0.0371664380100891 0.00481376112145174 -0.0314686710287568"
            rpy="0 0 0" />
        <mass
            value="0.0973570675974181" />
        <inertia
            ixx="0.00016"
            ixy="-0.00001"
            ixz="-0.00007"
            iyy="0.00019"
            iyz="0.00001"
            izz="0.00011" />
    </inertial>
    <visual>
        <origin
            xyz="0 0 0"
            rpy="0 0 0" />
        <geometry>
            <mesh
                filename="../../arx5p2Go1/meshes/arx5p2_meshes/link4.STL" />
        </geometry>
        <material
            name="dark_grey">
            <color
                rgba="0.5333333333333333 0.6078431372549019 0.7019607843137254 1.0" />
        </material>
    </visual>
    <collision>
        <origin
            xyz="0 0 0"
            rpy="0 0 0" />
        <geometry>
            <mesh
                filename="../../arx5p2Go1/meshes/arx5p2_meshes/link4.STL" />
        </geometry>
    </collision>
</link>
<joint name="zarx_j4"
    type="revolute">
    <origin
        xyz="0.245 0 -0.056"
        rpy="0 0 0" />
    <parent
        link="zarx_body3" />
    <child
        link="zarx_body4" />
    <axis
        xyz="0 1 0" />
    <limit
        lower="-1.5707913267948965"
        upper="1.5707913267948965"
        effort="3"
        velocity="3" />
</joint>
<link name="zarx_body5">
    <inertial>
        <origin
            xyz="0.00304994488747809 -4.95381751929073E-05 0.0540298691931158"
            rpy="0 0 0" />
        <mass
            value="0.59699075812436" />
        <inertia
            ixx="0.00072"
            ixy="0.00000"
            ixz="0.00005"
            iyy="0.00070"
            iyz="0.00000"
            izz="0.00021" />
    </inertial>
    <visual>
        <origin
            xyz="0 0 0"
            rpy="0 0 0" />
        <geometry>
            <mesh
                filename="../../arx5p2Go1/meshes/arx5p2_meshes/link5.STL" />
        </geometry>
        <material
            name="dark_grey">
            <color
                rgba="0.5333333333333333 0.6078431372549019 0.7019607843137254 1.0" />
        </material>
    </visual>
    <collision>
        <origin
            xyz="0 0 0"
            rpy="0 0 0" />
        <geometry>
            <mesh
                filename="../../arx5p2Go1/meshes/arx5p2_meshes/link5.STL" />
        </geometry>
    </collision>
</link>
<joint name="zarx_j5"
    type="revolute">
    <origin
        xyz="0.06675 0 -0.084"
        rpy="0 0 0" />
    <parent
        link="zarx_body4" />
    <child
        link="zarx_body5" />
    <axis
        xyz="0 0 1" />
    <limit
        lower="-1.5707913267948965"
        upper="1.5707913267948965"
        effort="3"
        velocity="3" />
</joint>
<link name="zarx_body6">
    <inertial>
        <origin
            xyz="0.0365156319457788 -1.4770288640792E-05 0.000265587114209737"
            rpy="0 0 0" />
        <mass
            value="0.315932346471264" />
        <inertia
            ixx="0.00031"
            ixy="0.00000"
            ixz="0.00000"
            iyy="0.00015"
            iyz="0.00000"
            izz="0.00038" />
    </inertial>
    <visual>
        <origin
            xyz="0 0 0"
            rpy="0 0 0" />
        <geometry>
            <mesh
                filename="../../arx5p2Go1/meshes/arx5p2_meshes/link6.STL" />
        </geometry>
        <material
            name="dark_grey">
            <color
                rgba="0.5333333333333333 0.6078431372549019 0.7019607843137254 1.0" />
        </material>
    </visual>
    <collision>
        <origin
            xyz="0 0 0"
            rpy="0 0 0" />
        <geometry>
            <mesh
                filename="../../arx5p2Go1/meshes/arx5p2_meshes/link6.STL" />
        </geometry>
    </collision>
</link>
<joint name="zarx_j6"
    type="revolute">
    <origin
        xyz="0.03045 0 0.084"
        rpy="-3.1416 0 0" />
    <parent
        link="zarx_body5" />
    <child
        link="zarx_body6" />
    <axis
        xyz="1 0 0" />
    <limit
        lower="-1.5707913267948965"
        upper="1.5707913267948965"
        effort="3"
        velocity="3" />
</joint>
<link name="zarx_body7">
    <inertial>
        <origin
            xyz="-0.000327642774520215 -0.00482005374028087 -0.00167540868720402"
            rpy="0 0 0" />
        <mass
            value="0.0484016660227936" />
        <inertia
            ixx="0.00001"
            ixy="0.00000"
            ixz="0.00000"
            iyy="0.00002"
            iyz="0.00000"
            izz="0.00002" />
    </inertial>
    <visual>
        <origin
            xyz="0 0 0"
            rpy="0 0 0" />
        <geometry>
            <mesh
                filename="../../arx5p2Go1/meshes/arx5p2_meshes/link7.STL" />
        </geometry>
        <material
            name="dark_grey">
            <color
                rgba="0.5333333333333333 0.6078431372549019 0.7019607843137254 1.0" />
        </material>
    </visual>
    <collision>
        <origin
            xyz="0 0 0"
            rpy="0 0 0" />
        <geometry>
            <mesh
                filename="../../arx5p2Go1/meshes/arx5p2_meshes/link7.STL" />
        </geometry>
    </collision>
</link>
<joint name="zarx_j7"
    type="prismatic">
    <origin
        xyz="0.073574 0.024629 0"
        rpy="0 0 0" />
    <parent
        link="zarx_body6" />
    <child
        link="zarx_body7" />
    <axis
        xyz="0 1 0" />
    <limit
        lower="0"
        upper="0.04765"
        effort="3"
        velocity="3" />
</joint>
<link name="zarx_body8">
    <inertial>
        <origin
            xyz="-0.000327643744208572 0.00482005363510456 0.000752972893839382"
            rpy="0 0 0" />
        <mass
            value="0.0484016646136083" />
        <inertia
            ixx="0.00001"
            ixy="0.00000"
            ixz="0.00000"
            iyy="0.00002"
            iyz="0.00000"
            izz="0.00002" />
    </inertial>
    <visual>
        <origin
            xyz="0 0 0"
            rpy="0 0 0" />
        <geometry>
            <mesh
                filename="../../arx5p2Go1/meshes/arx5p2_meshes/link8.STL" />
        </geometry>
        <material
            name="dark_grey">
            <color
                rgba="0.5333333333333333 0.6078431372549019 0.7019607843137254 1.0" />
        </material>
    </visual>
    <collision>
        <origin
            xyz="0 0 0"
            rpy="0 0 0" />
        <geometry>
            <mesh
                filename="../../arx5p2Go1/meshes/arx5p2_meshes/link8.STL" />
        </geometry>
    </collision>
</link>
<joint name="zarx_j8"
    type="prismatic">
    <origin
        xyz="0.073574 -0.024629 0"
        rpy="0 0 0" />
    <parent
        link="zarx_body6" />
    <child
        link="zarx_body8" />
    <axis
        xyz="0 -1 0" />
    <limit
        lower="0"
        upper="0.04765"
        effort="3"
        velocity="3" />
</joint>
  
  <!-- <xacro:stairs stairs="15" xpos="0" ypos="2.0" zpos="0" /> -->
</robot>
