<?xml version="1.0" encoding="utf-8"?>
<!-- =================================================================================== -->
<!-- |    This document was autogenerated by xacro from robot.xacro                    | -->
<!-- |    EDITING THIS FILE BY HAND IS NOT RECOMMENDED                                 | -->
<!-- =================================================================================== -->
<robot name="a1">
  <!-- dynamics inertial value -->
  <!-- trunk -->
  <!-- <xacro:property name="trunk_mass" value="5.660"/>
    <xacro:property name="trunk_com_x" value="0.012731"/>
    <xacro:property name="trunk_com_y" value="0.002186"/>
    <xacro:property name="trunk_com_z" value="0.000515"/>
    <xacro:property name="trunk_ixx" value="0.016839930"/>
    <xacro:property name="trunk_ixy" value="0.000083902"/>
    <xacro:property name="trunk_ixz" value="0.000597679"/>
    <xacro:property name="trunk_iyy" value="0.056579028"/>
    <xacro:property name="trunk_iyz" value="0.000025134"/>
    <xacro:property name="trunk_izz" value="0.064713601"/> -->
  <material name="black">
    <color rgba="0.0 0.0 0.0 1.0" />
  </material>
  <material name="blue">
    <color rgba="0.0 0.0 0.8 1.0" />
  </material>
  <material name="green">
    <color rgba="0.0 0.8 0.0 1.0" />
  </material>
  <material name="grey">
    <color rgba="0.2 0.2 0.2 1.0" />
  </material>
  <material name="silver">
    <color rgba="0.913725490196 0.913725490196 0.847058823529 1.0" />
  </material>
  <material name="orange">
    <color rgba="1.0 0.423529411765 0.0392156862745 1.0" />
  </material>
  <material name="brown">
    <color rgba="0.870588235294 0.811764705882 0.764705882353 1.0" />
  </material>
  <material name="red">
    <color rgba="0.8 0.0 0.0 1.0" />
  </material>

  <material name="self">
    <!-- <color rgba="0.5019607843137255 0.38823529411764707 0.43137254901960786 1.0"/>
     -->
    <color rgba="0.5647058823529412 0.5803921568627451 0.5764705882352941 1.0" />

  </material>

  <material name="white">
    <color rgba="1.0 1.0 1.0 1.0" />
  </material>
  <!-- <xacro:include filename="$(find a1_gazebo)/launch/stairs.urdf.xacro"/> -->
  <!-- <xacro:stairs stairs="15" xpos="0" ypos="0" zpos="0" /> -->
  <!-- Debug mode will hung up the robot, use "true" or "false" to switch it. -->
  <!-- <xacro:if value="$(arg DEBUG)">
        <link name="world"/>
        <joint name="base_static_joint" type="fixed">
            <origin rpy="0 0 0" xyz="0 0 0"/>
            <parent link="world"/>
            <child link="base"/>
        </joint>
    </xacro:if>  -->
  <link name="base">
    <visual>
      <origin rpy="1.57079632 0 0" xyz="0 0 0" />
      <geometry>
        <box size="0.001 0.001 0.001" />
      </geometry>
    </visual>
  </link>
  <joint name="floating_base" type="fixed" dont_collapse="true">
    <origin rpy="0 0 0" xyz="0 0 0" />
    <parent link="base" />
    <child link="trunk" />
  </joint>
  <link name="trunk">
    <visual>
      <origin rpy="1.57079632 0 0" xyz="0 0 0" />
      <geometry>
        <mesh filename="../meshes/trunk.dae" scale="1 1 1" />
      </geometry>
      <material name="self" />
    </visual>
    <collision>
      <origin rpy="1.57079632 0 0" xyz="0 0 0" />
      <geometry>
        <!-- <box size="0.267 0.194 0.114"/> -->
        <mesh filename="../meshes/trunk.dae" scale="1 1 1" />
      </geometry>
    </collision>
    <inertial>
      <origin rpy="1.57079632 0 0" xyz="0.0 0.0041 -0.0005" />
      <mass value="6.0" />
      <inertia ixx="0.0158533" ixy="-3.66e-05" ixz="-6.11e-05" iyy="0.0377999" iyz="-2.75e-05"
        izz="0.0456542" />
    </inertial>
  </link>
  <joint name="imu_joint" type="fixed">
    <parent link="trunk" />
    <child link="imu_link" />
    <origin rpy="0 0 0" xyz="0 0 0" />
  </joint>
  <link name="imu_link">
    <inertial>
      <mass value="0.001" />
      <origin rpy="1.57079632 0 0" xyz="0 0 0" />
      <inertia ixx="0.0001" ixy="0" ixz="0" iyy="0.0001" iyz="0" izz="0.0001" />
    </inertial>
    <visual>
      <origin rpy="1.57079632 0 0" xyz="0 0 0" />
      <geometry>
        <box size="0.001 0.001 0.001" />
      </geometry>
      <material name="red" />
    </visual>
    <collision>
      <origin rpy="1.57079632 0 0" xyz="0 0 0" />
      <geometry>
        <box size=".001 .001 .001" />
      </geometry>
    </collision>
  </link>
  <joint name="FR_hip_joint" type="revolute">
    <origin rpy="0 0 0" xyz="0.1805 -0.047 0" />
    <parent link="trunk" />
    <child link="FR_hip" />
    <axis xyz="1 0 0" />
    <dynamics damping="0.01" friction="0.2" />
    <limit effort="33.5" lower="-0.802851455917" upper="0.802851455917" velocity="21" />
  </joint>
  <link name="FR_hip">
    <visual>
      <origin rpy="4.712388 0 0" xyz="0 0 0" />
      <geometry>
        <mesh filename="../meshes/hip.dae" scale="1 1 1" />
      </geometry>
      <material name="self" />
    </visual>
    <!-- <collision>
      <origin rpy="3.141592 0 0" xyz="0 0 0"/>
      <geometry>
        <cylinder length="0.04" radius="0.046"/>
      </geometry>
    </collision> -->
    <inertial>
      <origin rpy="1.57079632 0 0" xyz="-0.003311 -0.000635 3.1e-05" />
      <mass value="0.696" />
      <inertia ixx="0.000469246" ixy="9.409e-06" ixz="-3.42e-07" iyy="0.00080749" iyz="4.66e-07"
        izz="0.000552929" />
    </inertial>
  </link>
  <joint name="FR_hip_fixed" type="fixed">
    <origin rpy="0 0 0" xyz="0 -0.081 0" />
    <parent link="FR_hip" />
    <child link="FR_thigh_shoulder" />
  </joint>
  <!-- this link is only for collision -->
  <link name="FR_thigh_shoulder">
    <!-- <collision>
      <origin rpy="3.141592 0 0" xyz="0 0 0"/>
      <geometry>
        <cylinder length="0.032" radius="0.041"/>
      </geometry>
    </collision> -->
  </link>
  <joint name="FR_thigh_joint" type="revolute">
    <origin rpy="0 0 0" xyz="0 -0.0838 0" />
    <parent link="FR_hip" />
    <child link="FR_thigh" />
    <axis xyz="0 1 0" />
    <dynamics damping="0.01" friction="0.2" />
    <limit effort="33.5" lower="-1.0471975512" upper="4.18879020479" velocity="21" />
  </joint>
  <link name="FR_thigh">
    <visual>
      <origin rpy="1.57079632 0 0" xyz="0 0 0" />
      <geometry>
        <mesh filename="../meshes/thigh_mirror.dae" scale="1 1 1" />
      </geometry>
      <material name="self" />
    </visual>
    <collision>
      <origin rpy="1.57079632 1.57079632679 0" xyz="0 0 -0.1" />
      <geometry>
        <box size="0.2 0.0245 0.034" />
      </geometry>
    </collision>
    <inertial>
      <origin rpy="1.57079632 0 0" xyz="-0.003237 0.022327 -0.027326" />
      <mass value="1.013" />
      <inertia ixx="0.005529065" ixy="-4.825e-06" ixz="0.000343869" iyy="0.005139339"
        iyz="-2.2448e-05" izz="0.001367788" />
    </inertial>
  </link>
  <joint name="FR_calf_joint" type="revolute">
    <origin rpy="0 0 0" xyz="0 0 -0.2" />
    <parent link="FR_thigh" />
    <child link="FR_calf" />
    <axis xyz="0 1 0" />
    <dynamics damping="0.01" friction="0.2" />
    <limit effort="33.5" lower="-2.69653369433" upper="-0.916297857297" velocity="21" />
  </joint>
  <link name="FR_calf">
    <visual>
      <origin rpy="1.57079632 0 0" xyz="0 0 0" />
      <geometry>
        <mesh filename="../meshes/calf.dae" scale="1 1 1" />
      </geometry>
      <material name="self" />
    </visual>
    <collision>
      <origin rpy="1.57079632 1.57079632679 0" xyz="0 0 -0.1" />
      <geometry>
        <box size="0.2 0.016 0.016" />
      </geometry>
    </collision>
    <inertial>
      <origin rpy="1.57079632 0 0" xyz="0.006435 0.0 -0.107388" />
      <mass value="0.166" />
      <inertia ixx="0.002997972" ixy="0.0" ixz="-0.000141163" iyy="0.003014022" iyz="0.0"
        izz="3.2426e-05" />
    </inertial>
  </link>
  <joint name="FR_foot_fixed" type="fixed" dont_collapse="true">
    <origin rpy="0 0 0" xyz="0 0 -0.2" />
    <parent link="FR_calf" />
    <child link="FR_foot" />
  </joint>
  <link name="FR_foot">
    <visual>
      <origin rpy="1.57079632 0 0" xyz="0 0 0" />
      <geometry>
        <sphere radius="0.01" />
      </geometry>
      <material name="self" />
    </visual>
    <collision>
      <origin rpy="1.57079632 0 0" xyz="0 0 0" />
      <geometry>
        <sphere radius="0.02" />
      </geometry>
    </collision>
    <inertial>
      <mass value="0.06" />
      <inertia ixx="9.6e-06" ixy="0.0" ixz="0.0" iyy="9.6e-06" iyz="0.0" izz="9.6e-06" />
    </inertial>
  </link>

  <joint name="FL_hip_joint" type="revolute">
    <origin rpy="0 0 0" xyz="0.1805 0.047 0" />
    <parent link="trunk" />
    <child link="FL_hip" />
    <axis xyz="1 0 0" />
    <dynamics damping="0.01" friction="0.2" />
    <limit effort="33.5" lower="-0.802851455917" upper="0.802851455917" velocity="21" />
  </joint>
  <link name="FL_hip">
    <visual>
      <origin rpy="1.57079632 0 0" xyz="0 0 0" />
      <geometry>
        <mesh filename="../meshes/hip.dae" scale="1 1 1" />
      </geometry>
      <material name="self" />
    </visual>
    <!-- <collision>
      <origin rpy="3.141592 0 0" xyz="0 0 0"/>
      <geometry>
        <cylinder length="0.04" radius="0.046"/>
      </geometry>
    </collision> -->
    <inertial>
      <origin rpy="1.57079632 0 0" xyz="-0.003311 0.000635 3.1e-05" />
      <mass value="0.696" />
      <inertia ixx="0.000469246" ixy="-9.409e-06" ixz="-3.42e-07" iyy="0.00080749" iyz="-4.66e-07"
        izz="0.000552929" />
    </inertial>
  </link>
  <joint name="FL_hip_fixed" type="fixed">
    <origin rpy="0 0 0" xyz="0 0.081 0" />
    <parent link="FL_hip" />
    <child link="FL_thigh_shoulder" />
  </joint>
  <!-- this link is only for collision -->
  <link name="FL_thigh_shoulder">
    <!-- <collision>
      <origin rpy="3.141592 0 0" xyz="0 0 0"/>
      <geometry>
        <cylinder length="0.032" radius="0.041"/>
      </geometry>
    </collision> -->
  </link>
  <joint name="FL_thigh_joint" type="revolute">
    <origin rpy="0 0 0" xyz="0 0.0838 0" />
    <parent link="FL_hip" />
    <child link="FL_thigh" />
    <axis xyz="0 1 0" />
    <dynamics damping="0.01" friction="0.2" />
    <limit effort="33.5" lower="-1.0471975512" upper="4.18879020479" velocity="21" />
  </joint>
  <link name="FL_thigh">
    <visual>
      <origin rpy="1.57079632 0 0" xyz="0 0 0" />
      <geometry>
        <mesh filename="../meshes/thigh.dae" scale="1 1 1" />
      </geometry>
      <material name="self" />
    </visual>
    <collision>
      <origin rpy="1.57079632 1.57079632679 0" xyz="0 0 -0.1" />
      <geometry>
        <box size="0.2 0.0245 0.034" />
      </geometry>
    </collision>
    <inertial>
      <origin rpy="1.57079632 0 0" xyz="-0.003237 -0.022327 -0.027326" />
      <mass value="1.013" />
      <inertia ixx="0.005529065" ixy="4.825e-06" ixz="0.000343869" iyy="0.005139339"
        iyz="2.2448e-05" izz="0.001367788" />
    </inertial>
  </link>
  <joint name="FL_calf_joint" type="revolute">
    <origin rpy="0 0 0" xyz="0 0 -0.2" />
    <parent link="FL_thigh" />
    <child link="FL_calf" />
    <axis xyz="0 1 0" />
    <dynamics damping="0.01" friction="0.2" />
    <limit effort="33.5" lower="-2.69653369433" upper="-0.916297857297" velocity="21" />
  </joint>
  <link name="FL_calf">
    <visual>
      <origin rpy="1.57079632 0 0" xyz="0 0 0" />
      <geometry>
        <mesh filename="../meshes/calf.dae" scale="1 1 1" />
      </geometry>
      <material name="self" />
    </visual>
    <collision>
      <origin rpy="1.57079632 1.57079632679 0" xyz="0 0 -0.1" />
      <geometry>
        <box size="0.2 0.016 0.016" />
      </geometry>
    </collision>
    <inertial>
      <origin rpy="1.57079632 0 0" xyz="0.006435 0.0 -0.107388" />
      <mass value="0.166" />
      <inertia ixx="0.002997972" ixy="0.0" ixz="-0.000141163" iyy="0.003014022" iyz="0.0"
        izz="3.2426e-05" />
    </inertial>
  </link>
  <joint name="FL_foot_fixed" type="fixed" dont_collapse="true">
    <origin rpy="0 0 0" xyz="0 0 -0.2" />
    <parent link="FL_calf" />
    <child link="FL_foot" />
  </joint>
  <link name="FL_foot">
    <visual>
      <origin rpy="1.57079632 0 0" xyz="0 0 0" />
      <geometry>
        <sphere radius="0.01" />
      </geometry>
      <material name="self" />
    </visual>
    <collision>
      <origin rpy="1.57079632 0 0" xyz="0 0 0" />
      <geometry>
        <sphere radius="0.02" />
      </geometry>
    </collision>
    <inertial>
      <mass value="0.06" />
      <inertia ixx="9.6e-06" ixy="0.0" ixz="0.0" iyy="9.6e-06" iyz="0.0" izz="9.6e-06" />
    </inertial>
  </link>

  <joint name="RR_hip_joint" type="revolute">
    <origin rpy="0 0 0" xyz="-0.1805 -0.047 0" />
    <parent link="trunk" />
    <child link="RR_hip" />
    <axis xyz="1 0 0" />
    <dynamics damping="0.01" friction="0.2" />
    <limit effort="33.5" lower="-0.802851455917" upper="0.802851455917" velocity="21" />
  </joint>
  <link name="RR_hip">
    <visual>
      <origin rpy="4.712388 3.14159265359 0" xyz="0 0 0" />
      <geometry>
        <mesh filename="../meshes/hip.dae" scale="1 1 1" />
      </geometry>
      <material name="self" />
    </visual>
    <!-- <collision>
      <origin rpy="3.141592 0 0" xyz="0 0 0"/>
      <geometry>
        <cylinder length="0.04" radius="0.046"/>
      </geometry>
    </collision> -->
    <inertial>
      <origin rpy="1.57079632 0 0" xyz="0.003311 -0.000635 3.1e-05" />
      <mass value="0.696" />
      <inertia ixx="0.000469246" ixy="-9.409e-06" ixz="3.42e-07" iyy="0.00080749" iyz="4.66e-07"
        izz="0.000552929" />
    </inertial>
  </link>
  <joint name="RR_hip_fixed" type="fixed">
    <origin rpy="0 0 0" xyz="0 -0.081 0" />
    <parent link="RR_hip" />
    <child link="RR_thigh_shoulder" />
  </joint>
  <!-- this link is only for collision -->
  <link name="RR_thigh_shoulder">
    <!-- <collision>
      <origin rpy="3.141592 0 0" xyz="0 0 0"/>
      <geometry>
        <cylinder length="0.032" radius="0.041"/>
      </geometry>
    </collision> -->
  </link>
  <joint name="RR_thigh_joint" type="revolute">
    <origin rpy="0 0 0" xyz="0 -0.0838 0" />
    <parent link="RR_hip" />
    <child link="RR_thigh" />
    <axis xyz="0 1 0" />
    <dynamics damping="0.01" friction="0.2" />
    <limit effort="33.5" lower="-1.0471975512" upper="4.18879020479" velocity="21" />
  </joint>
  <link name="RR_thigh">
    <visual>
      <origin rpy="1.57079632 0 0" xyz="0 0 0" />
      <geometry>
        <mesh filename="../meshes/thigh_mirror.dae" scale="1 1 1" />
      </geometry>
      <material name="self" />
    </visual>
    <collision>
      <origin rpy="1.57079632 1.57079632679 0" xyz="0 0 -0.1" />
      <geometry>
        <box size="0.2 0.0245 0.034" />
      </geometry>
    </collision>
    <inertial>
      <origin rpy="1.57079632 0 0" xyz="-0.003237 0.022327 -0.027326" />
      <mass value="1.013" />
      <inertia ixx="0.005529065" ixy="-4.825e-06" ixz="0.000343869" iyy="0.005139339"
        iyz="-2.2448e-05" izz="0.001367788" />
    </inertial>
  </link>
  <joint name="RR_calf_joint" type="revolute">
    <origin rpy="0 0 0" xyz="0 0 -0.2" />
    <parent link="RR_thigh" />
    <child link="RR_calf" />
    <axis xyz="0 1 0" />
    <dynamics damping="0.01" friction="0.2" />
    <limit effort="33.5" lower="-2.69653369433" upper="-0.916297857297" velocity="21" />
  </joint>
  <link name="RR_calf">
    <visual>
      <origin rpy="1.57079632 0 0" xyz="0 0 0" />
      <geometry>
        <mesh filename="../meshes/calf.dae" scale="1 1 1" />
      </geometry>
      <material name="self" />
    </visual>
    <collision>
      <origin rpy="1.57079632 1.57079632679 0" xyz="0 0 -0.1" />
      <geometry>
        <box size="0.2 0.016 0.016" />
      </geometry>
    </collision>
    <inertial>
      <origin rpy="1.57079632 0 0" xyz="0.006435 0.0 -0.107388" />
      <mass value="0.166" />
      <inertia ixx="0.002997972" ixy="0.0" ixz="-0.000141163" iyy="0.003014022" iyz="0.0"
        izz="3.2426e-05" />
    </inertial>
  </link>
  <joint name="RR_foot_fixed" type="fixed" dont_collapse="true">
    <origin rpy="0 0 0" xyz="0 0 -0.2" />
    <parent link="RR_calf" />
    <child link="RR_foot" />
  </joint>
  <link name="RR_foot">
    <visual>
      <origin rpy="1.57079632 0 0" xyz="0 0 0" />
      <geometry>
        <sphere radius="0.01" />
      </geometry>
      <material name="self" />
    </visual>
    <collision>
      <origin rpy="1.57079632 0 0" xyz="0 0 0" />
      <geometry>
        <sphere radius="0.02" />
      </geometry>
    </collision>
    <inertial>
      <mass value="0.06" />
      <inertia ixx="9.6e-06" ixy="0.0" ixz="0.0" iyy="9.6e-06" iyz="0.0" izz="9.6e-06" />
    </inertial>
  </link>

  <joint name="RL_hip_joint" type="revolute">
    <origin rpy="0 0 0" xyz="-0.1805 0.047 0" />
    <parent link="trunk" />
    <child link="RL_hip" />
    <axis xyz="1 0 0" />
    <dynamics damping="0.01" friction="0.2" />
    <limit effort="33.5" lower="-0.802851455917" upper="0.802851455917" velocity="21" />
  </joint>
  <link name="RL_hip">
    <visual>
      <origin rpy="1.57079632 3.14159265359 0" xyz="0 0 0" />
      <geometry>
        <mesh filename="../meshes/hip.dae" scale="1 1 1" />
      </geometry>
      <material name="self" />
    </visual>
    <!-- <collision>
      <origin rpy="3.141592 0 0" xyz="0 0 0"/>
      <geometry>
        <cylinder length="0.04" radius="0.046"/>
      </geometry>
    </collision> -->
    <inertial>
      <origin rpy="1.57079632 0 0" xyz="0.003311 0.000635 3.1e-05" />
      <mass value="0.696" />
      <inertia ixx="0.000469246" ixy="9.409e-06" ixz="3.42e-07" iyy="0.00080749" iyz="-4.66e-07"
        izz="0.000552929" />
    </inertial>
  </link>
  <joint name="RL_hip_fixed" type="fixed">
    <origin rpy="0 0 0" xyz="0 0.081 0" />
    <parent link="RL_hip" />
    <child link="RL_thigh_shoulder" />
  </joint>
  <!-- this link is only for collision -->
  <link name="RL_thigh_shoulder">
    <!-- <collision>
      <origin rpy="3.141592 0 0" xyz="0 0 0"/>
      <geometry>
        <cylinder length="0.032" radius="0.041"/>
      </geometry>
    </collision> -->
  </link>
  <joint name="RL_thigh_joint" type="revolute">
    <origin rpy="0 0 0" xyz="0 0.0838 0" />
    <parent link="RL_hip" />
    <child link="RL_thigh" />
    <axis xyz="0 1 0" />
    <dynamics damping="0.01" friction="0.2" />
    <limit effort="33.5" lower="-1.0471975512" upper="4.18879020479" velocity="21" />
  </joint>
  <link name="RL_thigh">
    <visual>
      <origin rpy="1.57079632 0 0" xyz="0 0 0" />
      <geometry>
        <mesh filename="../meshes/thigh.dae" scale="1 1 1" />
      </geometry>
      <material name="self" />
    </visual>
    <collision>
      <origin rpy="1.57079632 1.57079632679 0" xyz="0 0 -0.1" />
      <geometry>
        <box size="0.2 0.0245 0.034" />
      </geometry>
    </collision>
    <inertial>
      <origin rpy="1.57079632 0 0" xyz="-0.003237 -0.022327 -0.027326" />
      <mass value="1.013" />
      <inertia ixx="0.005529065" ixy="4.825e-06" ixz="0.000343869" iyy="0.005139339"
        iyz="2.2448e-05" izz="0.001367788" />
    </inertial>
  </link>
  <joint name="RL_calf_joint" type="revolute">
    <origin rpy="0 0 0" xyz="0 0 -0.2" />
    <parent link="RL_thigh" />
    <child link="RL_calf" />
    <axis xyz="0 1 0" />
    <dynamics damping="0.01" friction="0.2" />
    <limit effort="33.5" lower="-2.69653369433" upper="-0.916297857297" velocity="21" />
  </joint>
  <link name="RL_calf">
    <visual>
      <origin rpy="1.57079632 0 0" xyz="0 0 0" />
      <geometry>
        <mesh filename="../meshes/calf.dae" scale="1 1 1" />
      </geometry>
      <material name="self" />
    </visual>
    <collision>
      <origin rpy="1.57079632 1.57079632679 0" xyz="0 0 -0.1" />
      <geometry>
        <box size="0.2 0.016 0.016" />
      </geometry>
    </collision>
    <inertial>
      <origin rpy="1.57079632 0 0" xyz="0.006435 0.0 -0.107388" />
      <mass value="0.166" />
      <inertia ixx="0.002997972" ixy="0.0" ixz="-0.000141163" iyy="0.003014022" iyz="0.0"
        izz="3.2426e-05" />
    </inertial>
  </link>
  <joint name="RL_foot_fixed" type="fixed" dont_collapse="true">
    <origin rpy="0 0 0" xyz="0 0 -0.2" />
    <parent link="RL_calf" />
    <child link="RL_foot" />
  </joint>
  <link name="RL_foot">
    <visual>
      <origin rpy="1.57079632 0 0" xyz="0 0 0" />
      <geometry>
        <sphere radius="0.01" />
      </geometry>
      <material name="self" />
    </visual>
    <collision>
      <origin rpy="1.57079632 0 0" xyz="0 0 0" />
      <geometry>
        <sphere radius="0.02" />
      </geometry>
    </collision>
    <inertial>
      <mass value="0.06" />
      <inertia ixx="9.6e-06" ixy="0.0" ixz="0.0" iyy="9.6e-06" iyz="0.0" izz="9.6e-06" />
    </inertial>
  </link>



    <!-- widow x config -->
    <joint name="widow_mount" type="fixed">
      <origin rpy="0 0 0" xyz="0.03 0 0.057" />
      <parent link="base" />
      <child link="wx250s/base_link" />
  </joint>
  <link name="wx250s/base_link">
      <visual>
          <origin rpy="0 0 1.5707963267948966" xyz="0 0 0" />
          <geometry>
              <mesh filename="../../widowGo1/meshes/wx250s_meshes/wx250s_1_base.stl" scale="0.001 0.001 0.001" />
          </geometry>
          <material name="black" />
      </visual>
      <collision>
          <origin rpy="0 0 1.5707963267948966" xyz="0 0 0" />
          <geometry>
              <mesh filename="../../widowGo1/meshes/wx250s_meshes/wx250s_1_base.stl" scale="0.001 0.001 0.001" />
          </geometry>
      </collision>
      <inertial>
          <origin rpy="0 0 1.5707963267948966" xyz="-0.0380446000 0.0006138920 0.0193354000" />
          <mass value="0.538736" />
          <inertia ixx="0.0021150000" ixy="-0.0000163500" ixz="0.0000006998" iyy="0.0006921000"
              iyz="0.0000464200" izz="0.0025240000" />
      </inertial>
  </link>
  <joint name="widow_waist" type="revolute">
      <axis xyz="0 0 1" />
      <limit effort="10" lower="-3.141582653589793" upper="3.141582653589793"
          velocity="3.141592653589793" />
      <!-- <limit effort="10" velocity="3.141592653589793"/> -->
      <origin rpy="0 0 0" xyz="0 0 0.072" />
      <parent link="wx250s/base_link" />
      <child link="wx250s/shoulder_link" />
      <dynamics friction="0" />
  </joint>

  <link name="wx250s/shoulder_link">
      <visual>
          <origin rpy="0 0 1.5707963267948966" xyz="0 0 -0.003" />
          <geometry>
              <mesh filename="../../widowGo1/meshes/wx250s_meshes/wx250s_2_shoulder.stl"
                  scale="0.001 0.001 0.001" />
          </geometry>
          <material name="black" />
      </visual>
      <collision>
          <origin rpy="0 0 1.5707963267948966" xyz="0 0 -0.003" />
          <geometry>
              <mesh filename="../../widowGo1/meshes/wx250s_meshes/wx250s_2_shoulder.stl"
                  scale="0.001 0.001 0.001" />
          </geometry>
      </collision>
      <inertial>
          <origin rpy="0 0 1.5707963267948966" xyz="0.0000223482 0.0000414609 0.0066287000" />
          <mass value="0.480879" />
          <inertia ixx="0.0003790000" ixy="0.0000000022" ixz="-0.0000003561" iyy="0.0005557000"
              iyz="0.0000012245" izz="0.0005889000" />
      </inertial>
  </link>
  <joint name="widow_shoulder" type="revolute">
      <axis xyz="0 1 0" />
      <limit effort="20" lower="-1.8849555921538759" upper="1.9896753472735358"
          velocity="3.141592653589793" />
      <origin rpy="0 0 0" xyz="0 0 0.03865" />
      <parent link="wx250s/shoulder_link" />
      <child link="wx250s/upper_arm_link" />
      <dynamics friction="0" />
  </joint>

  <link name="wx250s/upper_arm_link">
      <visual>
          <origin rpy="0 0 1.5707963267948966" xyz="0 0 0" />
          <geometry>
              <mesh filename="../../widowGo1/meshes/wx250s_meshes/wx250s_3_upper_arm.stl"
                  scale="0.001 0.001 0.001" />
          </geometry>
          <material name="black" />
      </visual>
      <collision>
          <origin rpy="0 0 1.5707963267948966" xyz="0 0 0" />
          <geometry>
              <mesh filename="../../widowGo1/meshes/wx250s_meshes/wx250s_3_upper_arm.stl"
                  scale="0.001 0.001 0.001" />
          </geometry>
      </collision>
      <inertial>
          <origin rpy="0 0 1.5707963267948966" xyz="0.0171605000 0.0000002725 0.1913230000" />
          <mass value="0.430811" />
          <inertia ixx="0.0034630000" ixy="-0.0000000001" ixz="-0.0000000002" iyy="0.0035870000"
              iyz="0.0004272000" izz="0.0004566000" />
      </inertial>
  </link>
  <joint name="widow_elbow" type="revolute">
      <axis xyz="0 1 0" />
      <limit effort="15" lower="-2.1467549799530254" upper="1.6057029118347832"
          velocity="3.141592653589793" />
      <origin rpy="0 0 0" xyz="0.04975 0 0.25" />
      <parent link="wx250s/upper_arm_link" />
      <child link="wx250s/upper_forearm_link" />
      <dynamics friction="0" />
  </joint>

  <link name="wx250s/upper_forearm_link">
      <visual>
          <origin rpy="0 0 0" xyz="0 0 0" />
          <geometry>
              <mesh filename="../../widowGo1/meshes/wx250s_meshes/wx250s_4_upper_forearm.stl"
                  scale="0.001 0.001 0.001" />
          </geometry>
          <material name="black" />
      </visual>
      <collision>
          <origin rpy="0 0 0" xyz="0 0 0" />
          <geometry>
              <mesh filename="../../widowGo1/meshes/wx250s_meshes/wx250s_4_upper_forearm.stl"
                  scale="0.001 0.001 0.001" />
          </geometry>
      </collision>
      <inertial>
          <origin rpy="0 0 0" xyz="0.1079630000 0.0001158760 0" />
          <mass value="0.234589" />
          <inertia ixx="0.0000397100" ixy="0.0000023528" ixz="0" iyy="0.0008878000" iyz="0"
              izz="0.0008880000" />
      </inertial>
  </link>
  <joint name="widow_forearm_roll" type="revolute">
      <axis xyz="1 0 0" />
      <limit effort="2" lower="-3.141582653589793" upper="3.141582653589793"
          velocity="3.141592653589793" />
      <origin rpy="0 0 0" xyz="0.175 0 0" />
      <parent link="wx250s/upper_forearm_link" />
      <child link="wx250s/lower_forearm_link" />
      <dynamics friction="0" />
  </joint>

  <link name="wx250s/lower_forearm_link">
      <visual>
          <origin rpy="3.141592653589793 0 0" xyz="0 0 0" />
          <geometry>
              <mesh filename="../../widowGo1/meshes/wx250s_meshes/wx250s_5_lower_forearm.stl"
                  scale="0.001 0.001 0.001" />
          </geometry>
          <material name="black" />
      </visual>
      <collision>
          <origin rpy="3.141592653589793 0 0" xyz="0 0 0" />
          <geometry>
              <mesh filename="../../widowGo1/meshes/wx250s_meshes/wx250s_5_lower_forearm.stl"
                  scale="0.001 0.001 0.001" />
          </geometry>
      </collision>
      <inertial>
          <origin rpy="3.141592653589793 0 0" xyz="0.0374395000 0.0052225200 0" />
          <mass value="0.220991" />
          <inertia ixx="0.0000636900" ixy="-0.0000229200" ixz="0" iyy="0.0001677000" iyz="0"
              izz="0.0001834000" />
      </inertial>
  </link>
  <joint name="widow_wrist_angle" type="revolute">
      <axis xyz="0 1 0" />
      <limit effort="5" lower="-1.7453292519943295" upper="2.1467549799530254"
          velocity="3.141592653589793" />
      <origin rpy="0 0 0" xyz="0.075 0 0" />
      <parent link="wx250s/lower_forearm_link" />
      <child link="wx250s/wrist_link" />
      <dynamics friction="0" />
  </joint>

  <link name="wx250s/wrist_link">
      <visual>
          <origin rpy="0 0 1.5707963267948966" xyz="0 0 0" />
          <geometry>
              <mesh filename="../../widowGo1/meshes/wx250s_meshes/wx250s_6_wrist.stl"
                  scale="0.001 0.001 0.001" />
          </geometry>
          <material name="black" />
      </visual>
      <collision>
          <origin rpy="0 0 1.5707963267948966" xyz="0 0 0" />
          <geometry>
              <mesh filename="../../widowGo1/meshes/wx250s_meshes/wx250s_6_wrist.stl"
                  scale="0.001 0.001 0.001" />
          </geometry>
      </collision>
      <inertial>
          <origin rpy="0 0 1.5707963267948966" xyz="0.0423600000 -0.0000106630 0.0105770000" />
          <mass value="0.084957" />
          <inertia ixx="0.0000308200" ixy="0.0000000191" ixz="0.0000000023" iyy="0.0000282200"
              iyz="0.0000025481" izz="0.0000315200" />
      </inertial>
  </link>
  <joint name="widow_wrist_rotate" type="revolute">
      <axis xyz="1 0 0" />
      <limit effort="1" lower="-3.141582653589793" upper="3.141582653589793"
          velocity="3.141592653589793" />
      <origin rpy="0 0 0" xyz="0.065 0 0" />
      <parent link="wx250s/wrist_link" />
      <child link="wx250s/gripper_link" />
      <dynamics friction="0" />
  </joint>

  <link name="wx250s/gripper_link">
      <visual>
          <origin rpy="0 0 1.5707963267948966" xyz="-0.02 0 0" />
          <geometry>
              <mesh filename="../../widowGo1/meshes/wx250s_meshes/wx250s_7_gripper.stl"
                  scale="0.001 0.001 0.001" />
          </geometry>
          <material name="black" />
      </visual>
      <collision>
          <origin rpy="0 0 1.5707963267948966" xyz="-0.02 0 0" />
          <geometry>
              <mesh filename="../../widowGo1/meshes/wx250s_meshes/wx250s_7_gripper.stl"
                  scale="0.001 0.001 0.001" />
          </geometry>
      </collision>
      <inertial>
          <origin rpy="0 0 1.5707963267948966" xyz="0.0216310000 0.0000002516 0.0114100000" />
          <mass value="0.072885" />
          <inertia ixx="0.0000253700" ixy="0.0000000000" ixz="0.0000000000" iyy="0.0000183600"
              iyz="0.0000004340" izz="0.0000167400" />
      </inertial>
  </link>
  <joint name="ee_arm" type="fixed">
      <axis xyz="1 0 0" />
      <origin rpy="0 0 0" xyz="0.043 0 0" />
      <parent link="wx250s/gripper_link" />
      <child link="wx250s/ee_arm_link" />
  </joint>
  <link name="wx250s/ee_arm_link">
      <inertial>
          <mass value="0.001" />
          <inertia ixx="0.001" ixy="0" ixz="0" iyy="0.001" iyz="0" izz="0.001" />
      </inertial>
  </link>
  <joint name="gripper" type="fixed">
      <axis xyz="1 0 0" />
      <limit effort="1" velocity="3.141592653589793" />
      <origin rpy="0 0 0" xyz="0.0055 0 0" />
      <parent link="wx250s/ee_arm_link" />
      <child link="wx250s/gripper_prop_link" />
      <dynamics friction="0" />
  </joint>

  <link name="wx250s/gripper_prop_link">
      <visual>
          <origin rpy="0 0 1.5707963267948966" xyz="-0.0685 0 0" />
          <geometry>
              <mesh filename="../../widowGo1/meshes/wx250s_meshes/wx250s_8_gripper_prop.stl"
                  scale="0.001 0.001 0.001" />
          </geometry>
          <material name="black" />
      </visual>
      <collision>
          <origin rpy="0 0 1.5707963267948966" xyz="-0.0685 0 0" />
          <geometry>
              <mesh filename="../../widowGo1/meshes/wx250s_meshes/wx250s_8_gripper_prop.stl"
                  scale="0.001 0.001 0.001" />
          </geometry>
      </collision>
      <inertial>
          <origin rpy="0 0 1.5707963267948966" xyz="0.0008460000 -0.0000016817 0.0000420000" />
          <mass value="0.00434" />
          <inertia ixx="0.0000005923" ixy="0.0000000000" ixz="0.0000003195" iyy="0.0000011156"
              iyz="-0.0000000004" izz="0.0000005743" />
      </inertial>
  </link>
  <!-- If the AR tag is being used, then add the AR tag mount -->
  <!-- If the gripper bar is being used, then also add the gripper bar -->
  <joint name="gripper_bar" type="fixed">
      <axis xyz="1 0 0" />
      <origin rpy="0 0 0" xyz="0 0 0" />
      <parent link="wx250s/ee_arm_link" />
      <child link="wx250s/gripper_bar_link" />
  </joint>
  <link name="wx250s/gripper_bar_link">
      <visual>
          <origin rpy="0 0 1.5707963267948966" xyz="-0.063 0 0" />
          <geometry>
              <mesh filename="../../widowGo1/meshes/wx250s_meshes/wx250s_9_gripper_bar.stl"
                  scale="0.001 0.001 0.001" />
          </geometry>
          <material name="black" />
      </visual>
      <collision>
          <origin rpy="0 0 1.5707963267948966" xyz="-0.063 0 0" />
          <geometry>
              <mesh filename="../../widowGo1/meshes/wx250s_meshes/wx250s_9_gripper_bar.stl"
                  scale="0.001 0.001 0.001" />
          </geometry>
      </collision>
      <inertial>
          <origin rpy="0 0 1.5707963267948966" xyz="0.0096870000 0.0000008177 0.0049620000" />
          <mass value="0.034199" />
          <inertia ixx="0.0000074125" ixy="-0.0000000008" ixz="-0.0000000006" iyy="0.0000284300"
              iyz="-0.0000013889" izz="0.0000286000" />
      </inertial>
  </link>
  <joint name="ee_bar" type="fixed">
      <axis xyz="1 0 0" />
      <origin rpy="0 0 0" xyz="0.023 0 0" />
      <parent link="wx250s/gripper_bar_link" />
      <child link="wx250s/fingers_link" />
  </joint>
  <link name="wx250s/fingers_link">
      <inertial>
          <mass value="0.001" />
          <inertia ixx="0.001" ixy="0" ixz="0" iyy="0.001" iyz="0" izz="0.001" />
      </inertial>
  </link>
  <!-- If the gripper fingers are being used, add those as well -->
  <joint name="widow_left_finger" type="prismatic">
      <axis xyz="0 1 0" />
      <limit effort="5" lower="0.015" upper="0.037" velocity="1" />
      <origin rpy="0 0 0" xyz="0 0 0" />
      <parent link="wx250s/fingers_link" />
      <child link="wx250s/left_finger_link" />
      <dynamics friction="1000" />
  </joint>

  <link name="wx250s/left_finger_link">
      <visual>
          <origin rpy="3.141592653589793 3.141592653589793 0" xyz="0 0.005 0" />
          <geometry>
              <mesh filename="../../widowGo1/meshes/wx250s_meshes/wx250s_10_gripper_finger.stl"
                  scale="0.001 0.001 0.001" />
          </geometry>
          <material name="black" />
      </visual>
      <collision>
          <origin rpy="3.141592653589793 3.141592653589793 0" xyz="0 0.005 0" />
          <geometry>
              <mesh filename="../../widowGo1/meshes/wx250s_meshes/wx250s_10_gripper_finger.stl"
                  scale="0.001 0.001 0.001" />
          </geometry>
      </collision>
      <inertial>
          <origin rpy="3.141592653589793 3.141592653589793 1.5707963267948966"
              xyz="0.0138160000 0.0000000000 0.0000000000" />
          <mass value="0.016246" />
          <inertia ixx="0.0000047310" ixy="-0.0000004560" ixz="0.0000000000" iyy="0.0000015506"
              iyz="0.0000000000" izz="0.0000037467" />
      </inertial>
  </link>
  <joint name="widow_right_finger" type="prismatic">
      <axis xyz="0 1 0" />
      <limit effort="5" lower="-0.037" upper="-0.015" velocity="1" />
      <origin rpy="0 0 0" xyz="0 0 0" />
      <parent link="wx250s/fingers_link" />
      <child link="wx250s/right_finger_link" />
      <dynamics friction="1000" />
      <mimic joint="widow_left_finger" multiplier="-1" offset="0" />
  </joint>

  <link name="wx250s/right_finger_link">
      <visual>
          <origin rpy="0 3.141592653589793 0" xyz="0 -0.005 0" />
          <geometry>
              <mesh filename="../../widowGo1/meshes/wx250s_meshes/wx250s_10_gripper_finger.stl"
                  scale="0.001 0.001 0.001" />
          </geometry>
          <material name="black" />
      </visual>
      <collision>
          <origin rpy="0 3.141592653589793 0" xyz="0 -0.005 0" />
          <geometry>
              <mesh filename="../../widowGo1/meshes/wx250s_meshes/wx250s_10_gripper_finger.stl"
                  scale="0.001 0.001 0.001" />
          </geometry>
      </collision>
      <inertial>
          <origin rpy="0 3.141592653589793 1.5707963267948966"
              xyz="0.0138160000 0.0000000000  0.0000000000" />
          <mass value="0.016246" />
          <inertia ixx="0.0000047310" ixy="0.0000004560" ixz="0.0000000000" iyy="0.0000015506"
              iyz="0.0000000000" izz="0.0000037467" />
      </inertial>
  </link>
  <joint name="ee_gripper" type="fixed" dont_collapse="true">
      <axis xyz="1 0 0" />
      <origin rpy="0 0 0" xyz="0.027575 0 0" />
      <parent link="wx250s/fingers_link" />
      <child link="wx250s/ee_gripper_link" />
  </joint>
  <link name="wx250s/ee_gripper_link">
      <inertial>
          <mass value="0.001" />
          <inertia ixx="0.001" ixy="0" ixz="0" iyy="0.001" iyz="0" izz="0.001" />
      </inertial>
  </link>
  <!-- widow x config ends -->


  <!-- <xacro:stairs stairs="15" xpos="0" ypos="2.0" zpos="0" /> -->
</robot>