<?xml version="1.0"?>
<!-- =================================================================================== -->
<!-- |    This document was autogenerated by xacro from robot.xacro                    | -->
<!-- |    EDITING THIS FILE BY HAND IS NOT RECOMMENDED                                 | -->
<!-- =================================================================================== -->
<robot name="widowGo1">
    <material name="black">
        <color rgba="0.0 0.0 0.0 1.0" />
    </material>
    <material name="blue">
        <color rgba="0.0 0.0 0.8 1.0" />
    </material>
    <material name="green">
        <color rgba="0.0 0.8 0.0 1.0" />
    </material>
    <material name="grey">
        <color rgba="0.2 0.2 0.2 1.0" />
    </material>
    <material name="silver">
        <color rgba="0.913725490196 0.913725490196 0.847058823529 1.0" />
    </material>
    <material name="orange1">
        <color rgba="1.0 0.423529411765 0.0392156862745 1.0" />
    </material>
    <material name="brown">
        <color rgba="0.870588235294 0.811764705882 0.764705882353 1.0" />
    </material>
    <material name="red">
        <color rgba="0.8 0.0 0.0 1.0" />
    </material>
    <material name="white">
        <color rgba="1.0 1.0 1.0 1.0" />
    </material>

    <link name="base">
        <visual>
            <origin rpy="0 0 0" xyz="0 0 0" />
            <geometry>
                <box size="0.001 0.001 0.001" />
            </geometry>
        </visual>
    </link>

    <joint name="floating_base" type="fixed" dont_collapse="true">
        <origin rpy="0 0 0" xyz="0 0 0" />
        <parent link="base" />
        <child link="trunk" />
    </joint>
    <link name="trunk">
        <visual>
            <origin rpy="0 0 0" xyz="0 0 0" />
            <geometry>
                <mesh filename="../meshes/trunk.dae" scale="1 1 1" />
            </geometry>
            <material name="silver" />
        </visual>
        <collision>
            <origin rpy="0 0 0" xyz="0 0 0" />
            <geometry>
                <!-- <box size="0.3762 0.0935 0.114"/> -->
                <mesh filename="../meshes/trunk.dae" scale="1 1 1" />

            </geometry>
        </collision>
        <inertial>
            <origin rpy="0 0 0" xyz="0.0223 0.002 -0.0005" />
            <mass value="5.204" />
            <inertia ixx="0.0168352186" ixy="0.0004636141" ixz="0.0002367952" iyy="0.0656071082"
                iyz="3.6671e-05" izz="0.0742720659" />
        </inertial>
    </link>
    <joint name="imu_joint" type="fixed">
        <parent link="trunk" />
        <child link="imu_link" />
        <origin rpy="0 0 0" xyz="-0.01592 -0.06659 -0.00617" />
    </joint>
    <link name="imu_link">
        <inertial>
            <mass value="0.001" />
            <origin rpy="0 0 0" xyz="0 0 0" />
            <inertia ixx="0.0001" ixy="0" ixz="0" iyy="0.0001" iyz="0" izz="0.0001" />
        </inertial>
        <visual>
            <origin rpy="0 0 0" xyz="0 0 0" />
            <geometry>
                <box size="0.001 0.001 0.001" />
            </geometry>
            <!-- <material name="red"/> -->
        </visual>
        <collision>
            <origin rpy="0 0 0" xyz="0 0 0" />
            <geometry>
                <box size=".001 .001 .001" />
            </geometry>
        </collision>
    </link>
    <joint name="FR_hip_joint" type="revolute">
        <origin rpy="0 0 0" xyz="0.1881 -0.04675 0" />
        <parent link="trunk" />
        <child link="FR_hip" />
        <axis xyz="1 0 0" />
        <dynamics damping="0" friction="0" />
        <limit effort="23.7" lower="-1.0471975512" upper="1.0471975512" velocity="30.1" />
    </joint>
    <link name="FR_hip">
        <visual>
            <origin rpy="3.14159265359 0 0" xyz="0 0 0" />
            <geometry>
                <mesh filename="../meshes/hip.dae" scale="1 1 1" />
            </geometry>
            <material name="silver" />
        </visual>
        <!-- <collision>
      <origin rpy="1.57079632679 0 0" xyz="0 0 0"/>
      <geometry>
        <cylinder length="0.04" radius="0.046"/>
      </geometry>
    </collision> -->
        <inertial>
            <origin rpy="0 0 0" xyz="-0.00541 0.00074 6e-06" />
            <mass value="0.591" />
            <inertia ixx="0.000374268192" ixy="-3.6844422e-05" ixz="-9.86754e-07"
                iyy="0.000635923669" iyz="1.172894e-06" izz="0.000457647394" />
        </inertial>
    </link>
    <joint name="FR_hip_fixed" type="fixed">
        <origin rpy="0 0 0" xyz="0 -0.08 0" />
        <parent link="FR_hip" />
        <child link="FR_thigh_shoulder" />
    </joint>
    <!-- this link is only for collision -->
    <link name="FR_thigh_shoulder">
        <!-- <collision>
      <origin rpy="1.57079632679 0 0" xyz="0 0 0"/>
      <geometry>
        <cylinder length="0.032" radius="0.041"/>
      </geometry>
    </collision> -->
    </link>
    <joint name="FR_thigh_joint" type="revolute">
        <origin rpy="0 0 0" xyz="0 -0.08 0" />
        <parent link="FR_hip" />
        <child link="FR_thigh" />
        <axis xyz="0 1 0" />
        <dynamics damping="0" friction="0" />
        <limit effort="23.7" lower="-0.663225115758" upper="2.96705972839" velocity="30.1" />
    </joint>
    <link name="FR_thigh">
        <visual>
            <origin rpy="0 0 0" xyz="0 0 0" />
            <geometry>
                <mesh filename="../meshes/thigh_mirror.dae" scale="1 1 1" />
            </geometry>
            <material name="silver" />
        </visual>
        <collision>
            <origin rpy="0 1.57079632679 0" xyz="0 0 -0.1065" />
            <geometry>
                <box size="0.213 0.0245 0.034" />
            </geometry>
        </collision>
        <inertial>
            <origin rpy="0 0 0" xyz="-0.003468 0.018947 -0.032736" />
            <mass value="0.92" />
            <inertia ixx="0.005851561134" ixy="-1.783284e-06" ixz="0.000328291374"
                iyy="0.005596155105" iyz="-2.1430713e-05" izz="0.00107157026" />
        </inertial>
    </link>
    <joint name="FR_calf_joint" type="revolute">
        <origin rpy="0 0 0" xyz="0 0 -0.213" />
        <parent link="FR_thigh" />
        <child link="FR_calf" />
        <axis xyz="0 1 0" />
        <dynamics damping="0" friction="0" />
        <limit effort="23.7" lower="-2.72271363311" upper="-0.837758040957" velocity="30.1" />
    </joint>
    <link name="FR_calf">
        <visual>
            <origin rpy="0 0 0" xyz="0 0 0" />
            <geometry>
                <mesh filename="../meshes/calf.dae" scale="1 1 1" />
            </geometry>
            <material name="silver" />
        </visual>
        <collision>
            <origin rpy="0 1.57079632679 0" xyz="0 0 -0.1065" />
            <geometry>
                <box size="0.213 0.016 0.016" />
            </geometry>
        </collision>
        <inertial>
            <origin rpy="0 0 0" xyz="0.006286 0.001307 -0.122269" />
            <mass value="0.131" />
            <inertia ixx="0.002939186297" ixy="1.440899e-06" ixz="-0.00010535955"
                iyy="0.00295576935" iyz="-2.4397752e-05" izz="3.0273372e-05" />
        </inertial>
    </link>
    <joint name="FR_foot_fixed" type="fixed" dont_collapse="true">
        <origin rpy="0 0 0" xyz="0 0 -0.213" />
        <parent link="FR_calf" />
        <child link="FR_foot" />
    </joint>
    <link name="FR_foot">
        <visual>
            <origin rpy="0 0 0" xyz="0 0 0" />
            <geometry>
                <sphere radius="0.01" />
            </geometry>
            <material name="silver" />
        </visual>
        <collision>
            <origin rpy="0 0 0" xyz="0 0 0" />
            <geometry>
                <sphere radius="0.02" />
            </geometry>
        </collision>
        <inertial>
            <mass value="0.06" />
            <inertia ixx="9.6e-06" ixy="0.0" ixz="0.0" iyy="9.6e-06" iyz="0.0" izz="9.6e-06" />
        </inertial>
    </link>
    <transmission name="FR_hip_tran">
        <type>transmission_interface/SimpleTransmission</type>
        <joint name="FR_hip_joint">
            <hardwareInterface>hardware_interface/EffortJointInterface</hardwareInterface>
        </joint>
        <actuator name="FR_hip_motor">
            <hardwareInterface>hardware_interface/EffortJointInterface</hardwareInterface>
            <mechanicalReduction>1</mechanicalReduction>
        </actuator>
    </transmission>
    <transmission name="FR_thigh_tran">
        <type>transmission_interface/SimpleTransmission</type>
        <joint name="FR_thigh_joint">
            <hardwareInterface>hardware_interface/EffortJointInterface</hardwareInterface>
        </joint>
        <actuator name="FR_thigh_motor">
            <hardwareInterface>hardware_interface/EffortJointInterface</hardwareInterface>
            <mechanicalReduction>1</mechanicalReduction>
        </actuator>
    </transmission>
    <transmission name="FR_calf_tran">
        <type>transmission_interface/SimpleTransmission</type>
        <joint name="FR_calf_joint">
            <hardwareInterface>hardware_interface/EffortJointInterface</hardwareInterface>
        </joint>
        <actuator name="FR_calf_motor">
            <hardwareInterface>hardware_interface/EffortJointInterface</hardwareInterface>
            <mechanicalReduction>1</mechanicalReduction>
        </actuator>
    </transmission>
    <joint name="FL_hip_joint" type="revolute">
        <origin rpy="0 0 0" xyz="0.1881 0.04675 0" />
        <parent link="trunk" />
        <child link="FL_hip" />
        <axis xyz="1 0 0" />
        <dynamics damping="0" friction="0" />
        <limit effort="23.7" lower="-1.0471975512" upper="1.0471975512" velocity="30.1" />
    </joint>
    <link name="FL_hip">
        <visual>
            <origin rpy="0 0 0" xyz="0 0 0" />
            <geometry>
                <mesh filename="../meshes/hip.dae" scale="1 1 1" />
            </geometry>
            <material name="silver" />
        </visual>
        <!-- <collision>
      <origin rpy="1.57079632679 0 0" xyz="0 0 0"/>
      <geometry>
        <cylinder length="0.04" radius="0.046"/>
      </geometry>
    </collision> -->
        <inertial>
            <origin rpy="0 0 0" xyz="-0.00541 -0.00074 6e-06" />
            <mass value="0.591" />
            <inertia ixx="0.000374268192" ixy="3.6844422e-05" ixz="-9.86754e-07"
                iyy="0.000635923669" iyz="-1.172894e-06" izz="0.000457647394" />
        </inertial>
    </link>
    <joint name="FL_hip_fixed" type="fixed">
        <origin rpy="0 0 0" xyz="0 0.08 0" />
        <parent link="FL_hip" />
        <child link="FL_thigh_shoulder" />
    </joint>
    <!-- this link is only for collision -->
    <link name="FL_thigh_shoulder">
        <!-- <collision>
      <origin rpy="1.57079632679 0 0" xyz="0 0 0"/>
      <geometry>
        <cylinder length="0.032" radius="0.041"/>
      </geometry>
    </collision> -->
    </link>
    <joint name="FL_thigh_joint" type="revolute">
        <origin rpy="0 0 0" xyz="0 0.08 0" />
        <parent link="FL_hip" />
        <child link="FL_thigh" />
        <axis xyz="0 1 0" />
        <dynamics damping="0" friction="0" />
        <limit effort="23.7" lower="-0.663225115758" upper="2.96705972839" velocity="30.1" />
    </joint>
    <link name="FL_thigh">
        <visual>
            <origin rpy="0 0 0" xyz="0 0 0" />
            <geometry>
                <mesh filename="../meshes/thigh.dae" scale="1 1 1" />
            </geometry>
            <material name="silver" />
        </visual>
        <collision>
            <origin rpy="0 1.57079632679 0" xyz="0 0 -0.1065" />
            <geometry>
                <box size="0.213 0.0245 0.034" />
            </geometry>
        </collision>
        <inertial>
            <origin rpy="0 0 0" xyz="-0.003468 -0.018947 -0.032736" />
            <mass value="0.92" />
            <inertia ixx="0.005851561134" ixy="1.783284e-06" ixz="0.000328291374"
                iyy="0.005596155105" iyz="2.1430713e-05" izz="0.00107157026" />
        </inertial>
    </link>
    <joint name="FL_calf_joint" type="revolute">
        <origin rpy="0 0 0" xyz="0 0 -0.213" />
        <parent link="FL_thigh" />
        <child link="FL_calf" />
        <axis xyz="0 1 0" />
        <dynamics damping="0" friction="0" />
        <limit effort="23.7" lower="-2.72271363311" upper="-0.837758040957" velocity="30.1" />
    </joint>
    <link name="FL_calf">
        <visual>
            <origin rpy="0 0 0" xyz="0 0 0" />
            <geometry>
                <mesh filename="../meshes/calf.dae" scale="1 1 1" />
            </geometry>
            <material name="silver" />
        </visual>
        <collision>
            <origin rpy="0 1.57079632679 0" xyz="0 0 -0.1065" />
            <geometry>
                <box size="0.213 0.016 0.016" />
            </geometry>
        </collision>
        <inertial>
            <origin rpy="0 0 0" xyz="0.006286 0.001307 -0.122269" />
            <mass value="0.131" />
            <inertia ixx="0.002939186297" ixy="1.440899e-06" ixz="-0.00010535955"
                iyy="0.00295576935" iyz="-2.4397752e-05" izz="3.0273372e-05" />
        </inertial>
    </link>
    <joint name="FL_foot_fixed" type="fixed" dont_collapse="true">
        <origin rpy="0 0 0" xyz="0 0 -0.213" />
        <parent link="FL_calf" />
        <child link="FL_foot" />
    </joint>
    <link name="FL_foot">
        <visual>
            <origin rpy="0 0 0" xyz="0 0 0" />
            <geometry>
                <sphere radius="0.01" />
            </geometry>
            <material name="silver" />
        </visual>
        <collision>
            <origin rpy="0 0 0" xyz="0 0 0" />
            <geometry>
                <sphere radius="0.02" />
            </geometry>
        </collision>
        <inertial>
            <mass value="0.06" />
            <inertia ixx="9.6e-06" ixy="0.0" ixz="0.0" iyy="9.6e-06" iyz="0.0" izz="9.6e-06" />
        </inertial>
    </link>
    <transmission name="FL_hip_tran">
        <type>transmission_interface/SimpleTransmission</type>
        <joint name="FL_hip_joint">
            <hardwareInterface>hardware_interface/EffortJointInterface</hardwareInterface>
        </joint>
        <actuator name="FL_hip_motor">
            <hardwareInterface>hardware_interface/EffortJointInterface</hardwareInterface>
            <mechanicalReduction>1</mechanicalReduction>
        </actuator>
    </transmission>
    <transmission name="FL_thigh_tran">
        <type>transmission_interface/SimpleTransmission</type>
        <joint name="FL_thigh_joint">
            <hardwareInterface>hardware_interface/EffortJointInterface</hardwareInterface>
        </joint>
        <actuator name="FL_thigh_motor">
            <hardwareInterface>hardware_interface/EffortJointInterface</hardwareInterface>
            <mechanicalReduction>1</mechanicalReduction>
        </actuator>
    </transmission>
    <transmission name="FL_calf_tran">
        <type>transmission_interface/SimpleTransmission</type>
        <joint name="FL_calf_joint">
            <hardwareInterface>hardware_interface/EffortJointInterface</hardwareInterface>
        </joint>
        <actuator name="FL_calf_motor">
            <hardwareInterface>hardware_interface/EffortJointInterface</hardwareInterface>
            <mechanicalReduction>1</mechanicalReduction>
        </actuator>
    </transmission>
    <joint name="RR_hip_joint" type="revolute">
        <origin rpy="0 0 0" xyz="-0.1881 -0.04675 0" />
        <parent link="trunk" />
        <child link="RR_hip" />
        <axis xyz="1 0 0" />
        <dynamics damping="0" friction="0" />
        <limit effort="23.7" lower="-1.0471975512" upper="1.0471975512" velocity="30.1" />
    </joint>
    <link name="RR_hip">
        <visual>
            <origin rpy="3.14159265359 3.14159265359 0" xyz="0 0 0" />
            <geometry>
                <mesh filename="../meshes/hip.dae" scale="1 1 1" />
            </geometry>
            <material name="silver" />
        </visual>
        <!-- <collision>
      <origin rpy="1.57079632679 0 0" xyz="0 0 0"/>
      <geometry>
        <cylinder length="0.04" radius="0.046"/>
      </geometry>
    </collision> -->
        <inertial>
            <origin rpy="0 0 0" xyz="0.00541 0.00074 6e-06" />
            <mass value="0.591" />
            <inertia ixx="0.000374268192" ixy="3.6844422e-05" ixz="9.86754e-07" iyy="0.000635923669"
                iyz="1.172894e-06" izz="0.000457647394" />
        </inertial>
    </link>
    <joint name="RR_hip_fixed" type="fixed">
        <origin rpy="0 0 0" xyz="0 -0.08 0" />
        <parent link="RR_hip" />
        <child link="RR_thigh_shoulder" />
    </joint>
    <!-- this link is only for collision -->
    <link name="RR_thigh_shoulder">
        <!-- <collision>
      <origin rpy="1.57079632679 0 0" xyz="0 0 0"/>
      <geometry>
        <cylinder length="0.032" radius="0.041"/>
      </geometry>
    </collision> -->
    </link>
    <joint name="RR_thigh_joint" type="revolute">
        <origin rpy="0 0 0" xyz="0 -0.08 0" />
        <parent link="RR_hip" />
        <child link="RR_thigh" />
        <axis xyz="0 1 0" />
        <dynamics damping="0" friction="0" />
        <limit effort="23.7" lower="-0.663225115758" upper="2.96705972839" velocity="30.1" />
    </joint>
    <link name="RR_thigh">
        <visual>
            <origin rpy="0 0 0" xyz="0 0 0" />
            <geometry>
                <mesh filename="../meshes/thigh_mirror.dae" scale="1 1 1" />
            </geometry>
            <material name="silver" />
        </visual>
        <collision>
            <origin rpy="0 1.57079632679 0" xyz="0 0 -0.1065" />
            <geometry>
                <box size="0.213 0.0245 0.034" />
            </geometry>
        </collision>
        <inertial>
            <origin rpy="0 0 0" xyz="-0.003468 0.018947 -0.032736" />
            <mass value="0.92" />
            <inertia ixx="0.005851561134" ixy="-1.783284e-06" ixz="0.000328291374"
                iyy="0.005596155105" iyz="-2.1430713e-05" izz="0.00107157026" />
        </inertial>
    </link>
    <joint name="RR_calf_joint" type="revolute">
        <origin rpy="0 0 0" xyz="0 0 -0.213" />
        <parent link="RR_thigh" />
        <child link="RR_calf" />
        <axis xyz="0 1 0" />
        <dynamics damping="0" friction="0" />
        <limit effort="23.7" lower="-2.72271363311" upper="-0.837758040957" velocity="30.1" />
    </joint>
    <link name="RR_calf">
        <visual>
            <origin rpy="0 0 0" xyz="0 0 0" />
            <geometry>
                <mesh filename="../meshes/calf.dae" scale="1 1 1" />
            </geometry>
            <material name="silver" />
        </visual>
        <collision>
            <origin rpy="0 1.57079632679 0" xyz="0 0 -0.1065" />
            <geometry>
                <box size="0.213 0.016 0.016" />
            </geometry>
        </collision>
        <inertial>
            <origin rpy="0 0 0" xyz="0.006286 0.001307 -0.122269" />
            <mass value="0.131" />
            <inertia ixx="0.002939186297" ixy="1.440899e-06" ixz="-0.00010535955"
                iyy="0.00295576935" iyz="-2.4397752e-05" izz="3.0273372e-05" />
        </inertial>
    </link>
    <joint name="RR_foot_fixed" type="fixed" dont_collapse="true">
        <origin rpy="0 0 0" xyz="0 0 -0.213" />
        <parent link="RR_calf" />
        <child link="RR_foot" />
    </joint>
    <link name="RR_foot">
        <visual>
            <origin rpy="0 0 0" xyz="0 0 0" />
            <geometry>
                <sphere radius="0.01" />
            </geometry>
            <material name="silver" />
        </visual>
        <collision>
            <origin rpy="0 0 0" xyz="0 0 0" />
            <geometry>
                <sphere radius="0.02" />
            </geometry>
        </collision>
        <inertial>
            <mass value="0.06" />
            <inertia ixx="9.6e-06" ixy="0.0" ixz="0.0" iyy="9.6e-06" iyz="0.0" izz="9.6e-06" />
        </inertial>
    </link>
    <transmission name="RR_hip_tran">
        <type>transmission_interface/SimpleTransmission</type>
        <joint name="RR_hip_joint">
            <hardwareInterface>hardware_interface/EffortJointInterface</hardwareInterface>
        </joint>
        <actuator name="RR_hip_motor">
            <hardwareInterface>hardware_interface/EffortJointInterface</hardwareInterface>
            <mechanicalReduction>1</mechanicalReduction>
        </actuator>
    </transmission>
    <transmission name="RR_thigh_tran">
        <type>transmission_interface/SimpleTransmission</type>
        <joint name="RR_thigh_joint">
            <hardwareInterface>hardware_interface/EffortJointInterface</hardwareInterface>
        </joint>
        <actuator name="RR_thigh_motor">
            <hardwareInterface>hardware_interface/EffortJointInterface</hardwareInterface>
            <mechanicalReduction>1</mechanicalReduction>
        </actuator>
    </transmission>
    <transmission name="RR_calf_tran">
        <type>transmission_interface/SimpleTransmission</type>
        <joint name="RR_calf_joint">
            <hardwareInterface>hardware_interface/EffortJointInterface</hardwareInterface>
        </joint>
        <actuator name="RR_calf_motor">
            <hardwareInterface>hardware_interface/EffortJointInterface</hardwareInterface>
            <mechanicalReduction>1</mechanicalReduction>
        </actuator>
    </transmission>
    <joint name="RL_hip_joint" type="revolute">
        <origin rpy="0 0 0" xyz="-0.1881 0.04675 0" />
        <parent link="trunk" />
        <child link="RL_hip" />
        <axis xyz="1 0 0" />
        <dynamics damping="0" friction="0" />
        <limit effort="23.7" lower="-1.0471975512" upper="1.0471975512" velocity="30.1" />
    </joint>
    <link name="RL_hip">
        <visual>
            <origin rpy="0 3.14159265359 0" xyz="0 0 0" />
            <geometry>
                <mesh filename="../meshes/hip.dae" scale="1 1 1" />
            </geometry>
            <material name="silver" />
        </visual>
        <!-- <collision>
      <origin rpy="1.57079632679 0 0" xyz="0 0 0"/>
      <geometry>
        <cylinder length="0.04" radius="0.046"/>
      </geometry>
    </collision> -->
        <inertial>
            <origin rpy="0 0 0" xyz="0.00541 -0.00074 6e-06" />
            <mass value="0.591" />
            <inertia ixx="0.000374268192" ixy="-3.6844422e-05" ixz="9.86754e-07"
                iyy="0.000635923669" iyz="-1.172894e-06" izz="0.000457647394" />
        </inertial>
    </link>
    <joint name="RL_hip_fixed" type="fixed">
        <origin rpy="0 0 0" xyz="0 0.08 0" />
        <parent link="RL_hip" />
        <child link="RL_thigh_shoulder" />
    </joint>
    <!-- this link is only for collision -->
    <link name="RL_thigh_shoulder">
        <!-- <collision>
      <origin rpy="1.57079632679 0 0" xyz="0 0 0"/>
      <geometry>
        <cylinder length="0.032" radius="0.041"/>
      </geometry>
    </collision> -->
    </link>
    <joint name="RL_thigh_joint" type="revolute">
        <origin rpy="0 0 0" xyz="0 0.08 0" />
        <parent link="RL_hip" />
        <child link="RL_thigh" />
        <axis xyz="0 1 0" />
        <dynamics damping="0" friction="0" />
        <limit effort="23.7" lower="-0.663225115758" upper="2.96705972839" velocity="30.1" />
    </joint>
    <link name="RL_thigh">
        <visual>
            <origin rpy="0 0 0" xyz="0 0 0" />
            <geometry>
                <mesh filename="../meshes/thigh.dae" scale="1 1 1" />
            </geometry>
            <material name="silver" />
        </visual>
        <collision>
            <origin rpy="0 1.57079632679 0" xyz="0 0 -0.1065" />
            <geometry>
                <box size="0.213 0.0245 0.034" />
            </geometry>
        </collision>
        <inertial>
            <origin rpy="0 0 0" xyz="-0.003468 -0.018947 -0.032736" />
            <mass value="0.92" />
            <inertia ixx="0.005851561134" ixy="1.783284e-06" ixz="0.000328291374"
                iyy="0.005596155105" iyz="2.1430713e-05" izz="0.00107157026" />
        </inertial>
    </link>
    <joint name="RL_calf_joint" type="revolute">
        <origin rpy="0 0 0" xyz="0 0 -0.213" />
        <parent link="RL_thigh" />
        <child link="RL_calf" />
        <axis xyz="0 1 0" />
        <dynamics damping="0" friction="0" />
        <limit effort="23.7" lower="-2.72271363311" upper="-0.837758040957" velocity="30.1" />
    </joint>
    <link name="RL_calf">
        <visual>
            <origin rpy="0 0 0" xyz="0 0 0" />
            <geometry>
                <mesh filename="../meshes/calf.dae" scale="1 1 1" />
            </geometry>
            <material name="silver" />
        </visual>
        <collision>
            <origin rpy="0 1.57079632679 0" xyz="0 0 -0.1065" />
            <geometry>
                <box size="0.213 0.016 0.016" />
            </geometry>
        </collision>
        <inertial>
            <origin rpy="0 0 0" xyz="0.006286 0.001307 -0.122269" />
            <mass value="0.131" />
            <inertia ixx="0.002939186297" ixy="1.440899e-06" ixz="-0.00010535955"
                iyy="0.00295576935" iyz="-2.4397752e-05" izz="3.0273372e-05" />
        </inertial>
    </link>
    <joint name="RL_foot_fixed" type="fixed" dont_collapse="true">
        <origin rpy="0 0 0" xyz="0 0 -0.213" />
        <parent link="RL_calf" />
        <child link="RL_foot" />
    </joint>
    <link name="RL_foot">
        <visual>
            <origin rpy="0 0 0" xyz="0 0 0" />
            <geometry>
                <sphere radius="0.01" />
            </geometry>
            <material name="silver" />
        </visual>
        <collision>
            <origin rpy="0 0 0" xyz="0 0 0" />
            <geometry>
                <sphere radius="0.02" />
            </geometry>
        </collision>
        <inertial>
            <mass value="0.06" />
            <inertia ixx="9.6e-06" ixy="0.0" ixz="0.0" iyy="9.6e-06" iyz="0.0" izz="9.6e-06" />
        </inertial>
    </link>
    <transmission name="RL_hip_tran">
        <type>transmission_interface/SimpleTransmission</type>
        <joint name="RL_hip_joint">
            <hardwareInterface>hardware_interface/EffortJointInterface</hardwareInterface>
        </joint>
        <actuator name="RL_hip_motor">
            <hardwareInterface>hardware_interface/EffortJointInterface</hardwareInterface>
            <mechanicalReduction>1</mechanicalReduction>
        </actuator>
    </transmission>
    <transmission name="RL_thigh_tran">
        <type>transmission_interface/SimpleTransmission</type>
        <joint name="RL_thigh_joint">
            <hardwareInterface>hardware_interface/EffortJointInterface</hardwareInterface>
        </joint>
        <actuator name="RL_thigh_motor">
            <hardwareInterface>hardware_interface/EffortJointInterface</hardwareInterface>
            <mechanicalReduction>1</mechanicalReduction>
        </actuator>
    </transmission>
    <transmission name="RL_calf_tran">
        <type>transmission_interface/SimpleTransmission</type>
        <joint name="RL_calf_joint">
            <hardwareInterface>hardware_interface/EffortJointInterface</hardwareInterface>
        </joint>
        <actuator name="RL_calf_motor">
            <hardwareInterface>hardware_interface/EffortJointInterface</hardwareInterface>
            <mechanicalReduction>1</mechanicalReduction>
        </actuator>
    </transmission>

    <joint name="zarx5p2_mount" type="fixed">
        <origin rpy="0 0 0" xyz="0.0 0 0.057" />
        <parent link="base" />
        <child link="base_link" />
    </joint>
    <link name="base_link">
        <inertial>
            <origin
                xyz="-2.99718553142654E-05 3.05595229038557E-05 0.0273007719748077"
                rpy="0 0 0" />
            <mass
                value="0.440377203703276" />
            <inertia
                ixx="0.00017"
                ixy="0.00000"
                ixz="0.00000"
                iyy="0.00018"
                iyz="0.00000"
                izz="0.00016" />
        </inertial>
        <visual>
            <origin
                xyz="0 0 0"
                rpy="0 0 0" />
            <geometry>
                <mesh
                    filename="../meshes/arx5p2_meshes/base_link.STL" />
            </geometry>
            <material
                name="">
                <color
                    rgba="0.752941176470588 0.752941176470588 0.752941176470588 1" />
            </material>
        </visual>
        <collision>
            <origin
                xyz="0 0 0"
                rpy="0 0 0" />
            <geometry>
                <mesh
                    filename="../meshes/arx5p2_meshes/base_link.STL" />
            </geometry>
        </collision>
    </link>
    <link name="zarx_body1">
        <inertial>
            <origin
                xyz="0.00593840433365978 -0.00472599953587056 0.0175081397461388"
                rpy="0 0 0" />
            <mass
                value="0.0601565264856801" />
            <inertia
                ixx="0.00007"
                ixy="0.00000"
                ixz="0.00001"
                iyy="0.00003"
                iyz="-0.00001"
                izz="0.00007" />
        </inertial>
        <visual>
            <origin
                xyz="0 0 0"
                rpy="0 0 0" />
            <geometry>
                <mesh
                    filename="../meshes/arx5p2_meshes/link1.STL" />
            </geometry>
            <material
                name="">
                <color
                    rgba="0.752941176470588 0.752941176470588 0.752941176470588 1" />
            </material>
        </visual>
        <collision>
            <origin
                xyz="0 0 0"
                rpy="0 0 0" />
            <geometry>
                <mesh
                    filename="../meshes/arx5p2_meshes/link1.STL" />
            </geometry>
        </collision>
    </link>
    <joint name="zarx_j1"
        type="revolute">
        <origin
            xyz="0 0 0.0605"
            rpy="0 0 0" />
        <parent
            link="base_link" />
        <child
            link="zarx_body1" />
        <axis
            xyz="0 0 1" />
        <limit
            lower="-2.6179938779914944"
            upper="3.141592653589793"
            effort="15"
            velocity="3" />
    </joint>
    <link name="zarx_body2">
        <inertial>
            <origin
                xyz="-0.133119105376737 0.00212876404883936 0.000300078564270057"
                rpy="0 0 0" />
            <mass
                value="1.08500113729484" />
            <inertia
                ixx="0.00051"
                ixy="0.00000"
                ixz="-0.00006"
                iyy="0.01608"
                iyz="0.00000"
                izz="0.01613" />
        </inertial>
        <visual>
            <origin
                xyz="0 0 0"
                rpy="0 0 0" />
            <geometry>
                <mesh
                    filename="../meshes/arx5p2_meshes/link2.STL" />
            </geometry>
            <material
                name="">
                <color
                    rgba="0.752941176470588 0.752941176470588 0.752941176470588 1" />
            </material>
        </visual>
        <collision>
            <origin
                xyz="0 0 0"
                rpy="0 0 0" />
            <geometry>
                <mesh
                    filename="../meshes/arx5p2_meshes/link2.STL" />
            </geometry>
        </collision>
    </link>
    <joint name="zarx_j2"
        type="revolute">
        <origin
            xyz="0.02 0 0.04"
            rpy="0 0 0" />
        <parent
            link="zarx_body1" />
        <child
            link="zarx_body2" />
        <axis
            xyz="0 1 0" />
        <limit
            lower="0"
            upper="3.6651797625214253"
            effort="15"
            velocity="3" />
    </joint>
    <link name="zarx_body3">
        <inertial>
            <origin
                xyz="0.187211265543004 -0.000291648902073816 -0.051519273045457"
                rpy="0 0 0" />
            <mass
                value="0.503070815258962" />
            <inertia
                ixx="0.00033"
                ixy="-0.00007"
                ixz="-0.00039"
                iyy="0.00387"
                iyz="0.00001"
                izz="0.00384" />
        </inertial>
        <visual>
            <origin
                xyz="0 0 0"
                rpy="0 0 0" />
            <geometry>
                <mesh
                    filename="../meshes/arx5p2_meshes/link3.STL" />
            </geometry>
            <material
                name="">
                <color
                    rgba="0.752941176470588 0.752941176470588 0.752941176470588 1" />
            </material>
        </visual>
        <collision>
            <origin
                xyz="0 0 0"
                rpy="0 0 0" />
            <geometry>
                <mesh
                    filename="../meshes/arx5p2_meshes/link3.STL" />
            </geometry>
        </collision>
    </link>
    <joint name="zarx_j3"
        type="revolute">
        <origin
            xyz="-0.264 0 0"
            rpy="3.1416 0 0" />
        <parent
            link="zarx_body2" />
        <child
            link="zarx_body3" />
        <axis
            xyz="0 1 0" />
        <limit
            lower="0"
            upper="3.141582653589793"
            effort="15"
            velocity="3" />
    </joint>
    <link name="zarx_body4">
        <inertial>
            <origin
                xyz="0.0371664380100891 0.00481376112145174 -0.0314686710287568"
                rpy="0 0 0" />
            <mass
                value="0.0973570675974181" />
            <inertia
                ixx="0.00016"
                ixy="-0.00001"
                ixz="-0.00007"
                iyy="0.00019"
                iyz="0.00001"
                izz="0.00011" />
        </inertial>
        <visual>
            <origin
                xyz="0 0 0"
                rpy="0 0 0" />
            <geometry>
                <mesh
                    filename="../meshes/arx5p2_meshes/link4.STL" />
            </geometry>
            <material
                name="">
                <color
                    rgba="0.898039215686275 0.917647058823529 0.929411764705882 1" />
            </material>
        </visual>
        <collision>
            <origin
                xyz="0 0 0"
                rpy="0 0 0" />
            <geometry>
                <mesh
                    filename="../meshes/arx5p2_meshes/link4.STL" />
            </geometry>
        </collision>
    </link>
    <joint name="zarx_j4"
        type="revolute">
        <origin
            xyz="0.245 0 -0.056"
            rpy="0 0 0" />
        <parent
            link="zarx_body3" />
        <child
            link="zarx_body4" />
        <axis
            xyz="0 1 0" />
        <limit
            lower="-1.5707913267948965"
            upper="1.5707913267948965"
            effort="3"
            velocity="3" />
    </joint>
    <link name="zarx_body5">
        <inertial>
            <origin
                xyz="0.00304994488747809 -4.95381751929073E-05 0.0540298691931158"
                rpy="0 0 0" />
            <mass
                value="0.59699075812436" />
            <inertia
                ixx="0.00072"
                ixy="0.00000"
                ixz="0.00005"
                iyy="0.00070"
                iyz="0.00000"
                izz="0.00021" />
        </inertial>
        <visual>
            <origin
                xyz="0 0 0"
                rpy="0 0 0" />
            <geometry>
                <mesh
                    filename="../meshes/arx5p2_meshes/link5.STL" />
            </geometry>
            <material
                name="">
                <color
                    rgba="0.752941176470588 0.752941176470588 0.752941176470588 1" />
            </material>
        </visual>
        <collision>
            <origin
                xyz="0 0 0"
                rpy="0 0 0" />
            <geometry>
                <mesh
                    filename="../meshes/arx5p2_meshes/link5.STL" />
            </geometry>
        </collision>
    </link>
    <joint name="zarx_j5"
        type="revolute">
        <origin
            xyz="0.06675 0 -0.084"
            rpy="0 0 0" />
        <parent
            link="zarx_body4" />
        <child
            link="zarx_body5" />
        <axis
            xyz="0 0 1" />
        <limit
            lower="-1.5707913267948965"
            upper="1.5707913267948965"
            effort="3"
            velocity="3" />
    </joint>
    <link name="zarx_body6">
        <inertial>
            <origin
                xyz="0.0365156319457788 -1.4770288640792E-05 0.000265587114209737"
                rpy="0 0 0" />
            <mass
                value="0.315932346471264" />
            <inertia
                ixx="0.00031"
                ixy="0.00000"
                ixz="0.00000"
                iyy="0.00015"
                iyz="0.00000"
                izz="0.00038" />
        </inertial>
        <visual>
            <origin
                xyz="0 0 0"
                rpy="0 0 0" />
            <geometry>
                <mesh
                    filename="../meshes/arx5p2_meshes/link6.STL" />
            </geometry>
            <material
                name="">
                <color
                    rgba="0.898039215686275 0.917647058823529 0.929411764705882 1" />
            </material>
        </visual>
        <collision>
            <origin
                xyz="0 0 0"
                rpy="0 0 0" />
            <geometry>
                <mesh
                    filename="../meshes/arx5p2_meshes/link6.STL" />
            </geometry>
        </collision>
    </link>
    <joint name="zarx_j6"
        type="revolute">
        <origin
            xyz="0.03045 0 0.084"
            rpy="-3.1416 0 0" />
        <parent
            link="zarx_body5" />
        <child
            link="zarx_body6" />
        <axis
            xyz="1 0 0" />
        <limit
            lower="-1.5707913267948965"
            upper="1.5707913267948965"
            effort="3"
            velocity="3" />
    </joint>
    <link name="zarx_body7">
        <inertial>
            <origin
                xyz="-0.000327642774520215 -0.00482005374028087 -0.00167540868720402"
                rpy="0 0 0" />
            <mass
                value="0.0484016660227936" />
            <inertia
                ixx="0.00001"
                ixy="0.00000"
                ixz="0.00000"
                iyy="0.00002"
                iyz="0.00000"
                izz="0.00002" />
        </inertial>
        <visual>
            <origin
                xyz="0 0 0"
                rpy="0 0 0" />
            <geometry>
                <mesh
                    filename="../meshes/arx5p2_meshes/link7.STL" />
            </geometry>
            <material
                name="">
                <color
                    rgba="0.898039215686275 0.917647058823529 0.929411764705882 1" />
            </material>
        </visual>
        <collision>
            <origin
                xyz="0 0 0"
                rpy="0 0 0" />
            <geometry>
                <mesh
                    filename="../meshes/arx5p2_meshes/link7.STL" />
            </geometry>
        </collision>
    </link>
    <joint name="zarx_j7"
        type="prismatic">
        <origin
            xyz="0.073574 0.024629 0"
            rpy="0 0 0" />
        <parent
            link="zarx_body6" />
        <child
            link="zarx_body7" />
        <axis
            xyz="0 1 0" />
        <limit
            lower="0"
            upper="0.04765"
            effort="3"
            velocity="3" />
    </joint>
    <link name="zarx_body8">
        <inertial>
            <origin
                xyz="-0.000327643744208572 0.00482005363510456 0.000752972893839382"
                rpy="0 0 0" />
            <mass
                value="0.0484016646136083" />
            <inertia
                ixx="0.00001"
                ixy="0.00000"
                ixz="0.00000"
                iyy="0.00002"
                iyz="0.00000"
                izz="0.00002" />
        </inertial>
        <visual>
            <origin
                xyz="0 0 0"
                rpy="0 0 0" />
            <geometry>
                <mesh
                    filename="../meshes/arx5p2_meshes/link8.STL" />
            </geometry>
            <material
                name="">
                <color
                    rgba="0.898039215686275 0.917647058823529 0.929411764705882 1" />
            </material>
        </visual>
        <collision>
            <origin
                xyz="0 0 0"
                rpy="0 0 0" />
            <geometry>
                <mesh
                    filename="../meshes/arx5p2_meshes/link8.STL" />
            </geometry>
        </collision>
    </link>
    <joint name="zarx_j8"
        type="prismatic">
        <origin
            xyz="0.073574 -0.024629 0"
            rpy="0 0 0" />
        <parent
            link="zarx_body6" />
        <child
            link="zarx_body8" />
        <axis
            xyz="0 -1 0" />
        <limit
            lower="0"
            upper="0.04765"
            effort="3"
            velocity="3" />
    </joint>


</robot>