<?xml version="1.0" encoding="utf-8"?>
<!-- This URDF was automatically created by SolidWorks to URDF Exporter! Originally created by
Stephen Brawner (brawner@gmail.com) 
     Commit Version: 1.6.0-4-g7f85cfe  Build Version: 1.6.7995.38578
     For more information, please see http://wiki.ros.org/sw_urdf_exporter -->
<robot
    name="go2_description">

    <link name="base">
        <visual>
            <origin rpy="1.57079632 0 0" xyz="0 0 0" />
            <geometry>
                <box size="0.001 0.001 0.001" />
            </geometry>
        </visual>
    </link>


    <joint name="floating_base" type="fixed" dont_collapse="true">
        <origin rpy="0 0 0" xyz="0 0 0" />
        <parent link="base" />
        <child link="trunk" />
    </joint>

    <link
        name="trunk">
        <inertial>
            <origin
                xyz="0.021112 0 -0.005366"
                rpy="1.57079632 0 0" />
            <mass
                value="6.921" />
            <inertia
                ixx="0.02448"
                ixy="0.00012166"
                ixz="0.0014849"
                iyy="0.098077"
                iyz="-3.12E-05"
                izz="0.107" />
        </inertial>
        <visual>
            <origin
                xyz="0 0 0"
                rpy="1.57079632 0 0" />
            <geometry>
                <mesh
                    filename="../dae/base.dae" />
            </geometry>
            <material
                name="">
                <color
                    rgba="1 1 1 1" />
            </material>
        </visual>
        <collision>
            <origin rpy="1.57079632 0 0" xyz="0 0 0" />
            <geometry>
                <mesh
                    filename="../dae/base.dae" />
                <!-- <box size="0.3762 0.0935 0.114" /> -->
            </geometry>
        </collision>
    </link>


    <link
        name="Head_upper">
        <inertial>
            <origin
                xyz="0 0 0"
                rpy="1.57079632 0 0" />
            <mass
                value="0.001" />
            <inertia
                ixx="9.6e-06"
                ixy="0"
                ixz="0"
                iyy="9.6e-06"
                iyz="0"
                izz="9.6e-06" />
        </inertial>
        <collision>
            <origin
                xyz="0 0 0"
                rpy="1.57079632 0 0" />
            <geometry>
                <cylinder radius="0.05" length="0.09" />
            </geometry>
        </collision>
    </link>
    <joint
        name="Head_upper_joint"
        type="fixed">
        <origin
            xyz="0.285 0 0.01"
            rpy="0 0 0" />
        <parent
            link="base" />
        <child
            link="Head_upper" />
        <axis
            xyz="0 0 0" />
    </joint>
    <link
        name="Head_lower">
        <inertial>
            <origin
                xyz="0 0 0"
                rpy="1.57079632 0 0" />
            <mass
                value="0.001" />
            <inertia
                ixx="9.6e-06"
                ixy="0"
                ixz="0"
                iyy="9.6e-06"
                iyz="0"
                izz="9.6e-06" />
        </inertial>
        <collision>
            <origin
                xyz="0 0 0"
                rpy="1.57079632 0 0" />
            <geometry>
                <sphere radius="0.047" />
            </geometry>
        </collision>
    </link>
    <joint
        name="Head_lower_joint"
        type="fixed">
        <origin
            xyz="0.008 0 -0.07"
            rpy="0 0 0" />
        <parent
            link="Head_upper" />
        <child
            link="Head_lower" />
        <axis
            xyz="0 0 0" />
    </joint>
    <link
        name="FL_hip">
        <inertial>
            <origin
                xyz="-0.0054 0.00194 -0.000105"
                rpy="1.57079632 0 0" />
            <mass
                value="0.678" />
            <inertia
                ixx="0.00048"
                ixy="-3.01E-06"
                ixz="1.11E-06"
                iyy="0.000884"
                iyz="-1.42E-06"
                izz="0.000596" />
        </inertial>
        <visual>
            <origin
                xyz="0 0 0"
                rpy="1.57079632 0 0" />
            <geometry>
                <mesh
                    filename="../dae/hip.dae" />
            </geometry>
            <material
                name="">
                <color
                    rgba="1 1 1 1" />
            </material>
        </visual>
        <!-- <collision>
            <origin rpy="3.141592653589793 0 0" xyz="0 0.08 0" />
            <geometry>
                <cylinder length="0.04" radius="0.046" />
            </geometry>
        </collision> -->
    </link>
    <joint
        name="FL_hip_joint"
        type="revolute">
        <origin
            xyz="0.1934 0.0465 0"
            rpy="0 0 0" />
        <parent
            link="base" />
        <child
            link="FL_hip" />
        <axis
            xyz="1 0 0" />
        <limit
            lower="-1.0472"
            upper="1.0472"
            effort="23.7"
            velocity="30.1" />
    </joint>
    <link
        name="FL_thigh">
        <inertial>
            <origin
                xyz="-0.00374 -0.0223 -0.0327"
                rpy="1.57079632 0 0" />
            <mass
                value="1.152" />
            <inertia
                ixx="0.00584"
                ixy="8.72E-05"
                ixz="-0.000289"
                iyy="0.0058"
                iyz="0.000808"
                izz="0.00103" />
        </inertial>
        <visual>
            <origin
                xyz="0 0 0"
                rpy="1.57079632 0 0" />
            <geometry>
                <mesh
                    filename="../dae/thigh.dae" />
            </geometry>
            <material
                name="">
                <color
                    rgba="1 1 1 1" />
            </material>
        </visual>
        <collision>
            <origin rpy="1.57079632 1.5707963267948966 0" xyz="0 0 -0.1065" />
            <geometry>
                <box size="0.213 0.0245 0.034" />
            </geometry>
        </collision>
    </link>
    <joint
        name="FL_thigh_joint"
        type="revolute">
        <origin
            xyz="0 0.0955 0"
            rpy="0 0 0" />
        <parent
            link="FL_hip" />
        <child
            link="FL_thigh" />
        <axis
            xyz="0 1 0" />
        <limit
            lower="-1.5708"
            upper="3.4907"
            effort="23.7"
            velocity="30.1" />
    </joint>
    <link
        name="FL_calf">
        <inertial>
            <origin
                xyz="0.00548 -0.000975 -0.115"
                rpy="1.57079632 0 0" />
            <mass
                value="0.154" />
            <inertia
                ixx="0.00108"
                ixy="3.4E-07"
                ixz="1.72E-05"
                iyy="0.0011"
                iyz="8.28E-06"
                izz="3.29E-05" />
        </inertial>
        <visual>
            <origin
                xyz="0 0 0"
                rpy="1.57079632 0 0" />
            <geometry>
                <mesh
                    filename="../dae/calf.dae" />
            </geometry>
            <material
                name="">
                <color
                    rgba="1 1 1 1" />
            </material>
        </visual>
        <collision>
            <origin rpy="1.57079632 -0.21 0" xyz="0.008 0 -0.06" />
            <geometry>
                <cylinder length="0.12" radius="0.012" />
            </geometry>
        </collision>
    </link>
    <joint
        name="FL_calf_joint"
        type="revolute">
        <origin
            xyz="0 0 -0.213"
            rpy="0 0 0" />
        <parent
            link="FL_thigh" />
        <child
            link="FL_calf" />
        <axis
            xyz="0 1 0" />
        <limit
            lower="-2.7227"
            upper="-0.83776"
            effort="45.43"
            velocity="15.70" />
    </joint>
    <link
        name="FL_calflower">
        <collision>
            <origin rpy="1.57079632 0 0" xyz="0 0 0" />
            <geometry>
                <cylinder length="0.065" radius="0.011" />
            </geometry>
        </collision>
    </link>
    <joint
        name="FL_calflower_joint"
        type="fixed">
        <origin
            xyz="0.020 0 -0.148"
            rpy="0 0.05 0" />
        <parent
            link="FL_calf" />
        <child
            link="FL_calflower" />
        <axis
            xyz="0 0 0" />
    </joint>
    <link
        name="FL_calflower1">
        <collision>
            <origin rpy="1.57079632 0 0" xyz="0 0 0" />
            <geometry>
                <cylinder length="0.03" radius="0.0155" />
            </geometry>
        </collision>
    </link>
    <joint
        name="FL_calflower1_joint"
        type="fixed">
        <origin
            xyz="-0.01 0 -0.04"
            rpy="0 0.48 0" />
        <parent
            link="FL_calflower" />
        <child
            link="FL_calflower1" />
        <axis
            xyz="0 0 0" />
    </joint>
    <link
        name="FL_foot">
        <inertial>
            <origin
                xyz="0 0 0"
                rpy="1.57079632 0 0" />
            <mass
                value="0.04" />
            <inertia
                ixx="9.6e-06"
                ixy="0"
                ixz="0"
                iyy="9.6e-06"
                iyz="0"
                izz="9.6e-06" />
        </inertial>
        <visual>
            <origin
                xyz="0 0 0"
                rpy="1.57079632 0 0" />
            <geometry>
                <mesh
                    filename="../dae/foot.dae" />
            </geometry>
            <material
                name="">
                <color
                    rgba="1 1 1 1" />
            </material>
        </visual>
        <collision>
            <origin rpy="1.57079632 0 0" xyz="-0.002 0 0" />
            <geometry>
                <sphere radius="0.022" />
            </geometry>
        </collision>
    </link>
    <joint
        name="FL_foot_joint"
        type="fixed" dont_collapse="true">
        <origin
            xyz="0 0 -0.213"
            rpy="0 0 0" />
        <parent
            link="FL_calf" />
        <child
            link="FL_foot" />
        <axis
            xyz="0 0 0" />
    </joint>
    <link
        name="FR_hip">
        <inertial>
            <origin
                xyz="-0.0054 -0.00194 -0.000105"
                rpy="1.57079632 0 0" />
            <mass
                value="0.678" />
            <inertia
                ixx="0.00048"
                ixy="3.01E-06"
                ixz="1.11E-06"
                iyy="0.000884"
                iyz="1.42E-06"
                izz="0.000596" />
        </inertial>
        <visual>
            <origin
                xyz="0 0 0"
                rpy="4.71238898 0 0" />
            <geometry>
                <mesh
                    filename="../dae/hip.dae" />
            </geometry>
            <material
                name="">
                <color
                    rgba="1 1 1 1" />
            </material>
        </visual>
        <!-- <collision>
            <origin rpy="3.141592 0 0" xyz="0 -0.08 0" />
            <geometry>
                <cylinder length="0.04" radius="0.046" />
            </geometry>
        </collision> -->
    </link>
    <joint
        name="FR_hip_joint"
        type="revolute">
        <origin
            xyz="0.1934 -0.0465 0"
            rpy="0 0 0" />
        <parent
            link="base" />
        <child
            link="FR_hip" />
        <axis
            xyz="1 0 0" />
        <limit
            lower="-1.0472"
            upper="1.0472"
            effort="23.7"
            velocity="30.1" />
    </joint>
    <link
        name="FR_thigh">
        <inertial>
            <origin
                xyz="-0.00374 0.0223 -0.0327"
                rpy="1.57079632 0 0" />
            <mass
                value="1.152" />
            <inertia
                ixx="0.00584"
                ixy="-8.72E-05"
                ixz="-0.000289"
                iyy="0.0058"
                iyz="-0.000808"
                izz="0.00103" />
        </inertial>
        <visual>
            <origin
                xyz="0 0 0"
                rpy="1.57079632 0 0" />
            <geometry>
                <mesh
                    filename="../dae/thigh_mirror.dae" />
            </geometry>
            <material
                name="">
                <color
                    rgba="1 1 1 1" />
            </material>
        </visual>
        <collision>
            <origin rpy="1.57079632 1.5707963267948966 0" xyz="0 0 -0.1065" />
            <geometry>
                <box size="0.213 0.0245 0.034" />
            </geometry>
        </collision>
    </link>
    <joint
        name="FR_thigh_joint"
        type="revolute">
        <origin
            xyz="0 -0.0955 0"
            rpy="0 0 0" />
        <parent
            link="FR_hip" />
        <child
            link="FR_thigh" />
        <axis
            xyz="0 1 0" />
        <limit
            lower="-1.5708"
            upper="3.4907"
            effort="23.7"
            velocity="30.1" />
    </joint>
    <link
        name="FR_calf">
        <inertial>
            <origin
                xyz="0.00548 0.000975 -0.115"
                rpy="1.57079632 0 0" />
            <mass
                value="0.154" />
            <inertia
                ixx="0.00108"
                ixy="-3.4E-07"
                ixz="1.72E-05"
                iyy="0.0011"
                iyz="-8.28E-06"
                izz="3.29E-05" />
        </inertial>
        <visual>
            <origin
                xyz="0 0 0"
                rpy="1.57079632 0 0" />
            <geometry>
                <mesh
                    filename="../dae/calf_mirror.dae" />
            </geometry>
            <material
                name="">
                <color
                    rgba="1 1 1 1" />
            </material>
        </visual>
        <collision>
            <origin rpy="1.57079632 -0.2 0" xyz="0.01 0 -0.06" />
            <geometry>
                <cylinder length="0.12" radius="0.013" />
            </geometry>
        </collision>
    </link>
    <joint
        name="FR_calf_joint"
        type="revolute">
        <origin
            xyz="0 0 -0.213"
            rpy="0 0 0" />
        <parent
            link="FR_thigh" />
        <child
            link="FR_calf" />
        <axis
            xyz="0 1 0" />
        <limit
            lower="-2.7227"
            upper="-0.83776"
            effort="45.43"
            velocity="15.70" />
    </joint>
    <link
        name="FR_calflower">
        <collision>
            <origin rpy="1.57079632 0 0" xyz="0 0 0" />
            <geometry>
                <cylinder length="0.065" radius="0.011" />
            </geometry>
        </collision>
    </link>
    <joint
        name="FR_calflower_joint"
        type="fixed">
        <origin
            xyz="0.020 0 -0.148"
            rpy="0 0.05 0" />
        <parent
            link="FR_calf" />
        <child
            link="FR_calflower" />
        <axis
            xyz="0 0 0" />
    </joint>
    <link
        name="FR_calflower1">
        <collision>
            <origin rpy="1.57079632 0 0" xyz="0 0 0" />
            <geometry>
                <cylinder length="0.03" radius="0.0155" />
            </geometry>
        </collision>
    </link>
    <joint
        name="FR_calflower1_joint"
        type="fixed">
        <origin
            xyz="-0.01 0 -0.04"
            rpy="0 0.48 0" />
        <parent
            link="FR_calflower" />
        <child
            link="FR_calflower1" />
        <axis
            xyz="0 0 0" />
    </joint>
    <link
        name="FR_foot">
        <inertial>
            <origin
                xyz="0 0 0"
                rpy="1.57079632 0 0" />
            <mass
                value="0.04" />
            <inertia
                ixx="9.6e-06"
                ixy="0"
                ixz="0"
                iyy="9.6e-06"
                iyz="0"
                izz="9.6e-06" />
        </inertial>
        <visual>
            <origin
                xyz="0 0 0"
                rpy="1.57079632 0 0" />
            <geometry>
                <mesh
                    filename="../dae/foot.dae" />
            </geometry>
            <material
                name="">
                <color
                    rgba="1 1 1 1" />
            </material>
        </visual>
        <collision>
            <origin rpy="1.57079632 0 0" xyz="-0.002 0 0" />
            <geometry>
                <sphere radius="0.022" />
            </geometry>
        </collision>
    </link>
    <joint
        name="FR_foot_joint"
        type="fixed" dont_collapse="true">
        <origin
            xyz="0 0 -0.213"
            rpy="0 0 0" />
        <parent
            link="FR_calf" />
        <child
            link="FR_foot" />
        <axis
            xyz="0 0 0" />
    </joint>
    <link
        name="RL_hip">
        <inertial>
            <origin
                xyz="0.0054 0.00194 -0.000105"
                rpy="1.57079632 0 0" />
            <mass
                value="0.678" />
            <inertia
                ixx="0.00048"
                ixy="3.01E-06"
                ixz="-1.11E-06"
                iyy="0.000884"
                iyz="-1.42E-06"
                izz="0.000596" />
        </inertial>
        <visual>
            <origin
                xyz="0 0 0"
                rpy="1.57079632 3.1415 0" />
            <geometry>
                <mesh
                    filename="../dae/hip.dae" />
            </geometry>
            <material
                name="">
                <color
                    rgba="1 1 1 1" />
            </material>
        </visual>
        <!-- <collision>
            <origin rpy="3.141592 0 0" xyz="0 0.08 0" />
            <geometry>
                <cylinder length="0.04" radius="0.046" />
            </geometry>
        </collision> -->
    </link>
    <joint
        name="RL_hip_joint"
        type="revolute">
        <origin
            xyz="-0.1934 0.0465 0"
            rpy="0 0 0" />
        <parent
            link="base" />
        <child
            link="RL_hip" />
        <axis
            xyz="1 0 0" />
        <limit
            lower="-1.0472"
            upper="1.0472"
            effort="23.7"
            velocity="30.1" />
    </joint>
    <link
        name="RL_thigh">
        <inertial>
            <origin
                xyz="-0.00374 -0.0223 -0.0327"
                rpy="1.57079632 0 0" />
            <mass
                value="1.152" />
            <inertia
                ixx="0.00584"
                ixy="8.72E-05"
                ixz="-0.000289"
                iyy="0.0058"
                iyz="0.000808"
                izz="0.00103" />
        </inertial>
        <visual>
            <origin
                xyz="0 0 0"
                rpy="1.57079632 0 0" />
            <geometry>
                <mesh
                    filename="../dae/thigh.dae" />
            </geometry>
            <material
                name="">
                <color
                    rgba="1 1 1 1" />
            </material>
        </visual>
        <collision>
            <origin rpy="1.57079632 1.5707963267948966 0" xyz="0 0 -0.1065" />
            <geometry>
                <box size="0.213 0.0245 0.034" />
            </geometry>
        </collision>
    </link>
    <joint
        name="RL_thigh_joint"
        type="revolute">
        <origin
            xyz="0 0.0955 0"
            rpy="0 0 0" />
        <parent
            link="RL_hip" />
        <child
            link="RL_thigh" />
        <axis
            xyz="0 1 0" />
        <limit
            lower="-0.5236"
            upper="4.5379"
            effort="23.7"
            velocity="30.1" />
    </joint>
    <link
        name="RL_calf">
        <inertial>
            <origin
                xyz="0.00548 -0.000975 -0.115"
                rpy="1.57079632 0 0" />
            <mass
                value="0.154" />
            <inertia
                ixx="0.00108"
                ixy="3.4E-07"
                ixz="1.72E-05"
                iyy="0.0011"
                iyz="8.28E-06"
                izz="3.29E-05" />
        </inertial>
        <visual>
            <origin
                xyz="0 0 0"
                rpy="1.57079632 0 0" />
            <geometry>
                <mesh
                    filename="../dae/calf.dae" />
            </geometry>
            <material
                name="">
                <color
                    rgba="1 1 1 1" />
            </material>
        </visual>
        <collision>
            <origin rpy="1.57079632 -0.2 0" xyz="0.01 0 -0.06" />
            <geometry>
                <cylinder length="0.12" radius="0.013" />
            </geometry>
        </collision>
    </link>
    <joint
        name="RL_calf_joint"
        type="revolute">
        <origin
            xyz="0 0 -0.213"
            rpy="0 0 0" />
        <parent
            link="RL_thigh" />
        <child
            link="RL_calf" />
        <axis
            xyz="0 1 0" />
        <limit
            lower="-2.7227"
            upper="-0.83776"
            effort="45.43"
            velocity="15.70" />
    </joint>
    <link
        name="RL_calflower">
        <collision>
            <origin rpy="1.57079632 0 0" xyz="0 0 0" />
            <geometry>
                <cylinder length="0.065" radius="0.011" />
            </geometry>
        </collision>
    </link>
    <joint
        name="RL_calflower_joint"
        type="fixed">
        <origin
            xyz="0.020 0 -0.148"
            rpy="0 0.05 0" />
        <parent
            link="RL_calf" />
        <child
            link="RL_calflower" />
        <axis
            xyz="0 0 0" />
    </joint>
    <link
        name="RL_calflower1">
        <collision>
            <origin rpy="1.57079632 0 0" xyz="0 0 0" />
            <geometry>
                <cylinder length="0.03" radius="0.0155" />
            </geometry>
        </collision>
    </link>
    <joint
        name="RL_calflower1_joint"
        type="fixed">
        <origin
            xyz="-0.01 0 -0.04"
            rpy="0 0.48 0" />
        <parent
            link="RL_calflower" />
        <child
            link="RL_calflower1" />
        <axis
            xyz="0 0 0" />
    </joint>
    <link
        name="RL_foot">
        <inertial>
            <origin
                xyz="0 0 0"
                rpy="1.57079632 0 0" />
            <mass
                value="0.04" />
            <inertia
                ixx="9.6e-06"
                ixy="0"
                ixz="0"
                iyy="9.6e-06"
                iyz="0"
                izz="9.6e-06" />
        </inertial>
        <visual>
            <origin
                xyz="0 0 0"
                rpy="1.57079632 0 0" />
            <geometry>
                <mesh
                    filename="../dae/foot.dae" />
            </geometry>
            <material
                name="">
                <color
                    rgba="1 1 1 1" />
            </material>
        </visual>
        <collision>
            <origin rpy="1.57079632 0 0" xyz="-0.002 0 0" />
            <geometry>
                <sphere radius="0.022" />
            </geometry>
        </collision>
    </link>
    <joint
        name="RL_foot_joint"
        type="fixed" dont_collapse="true">
        <origin
            xyz="0 0 -0.213"
            rpy="0 0 0" />
        <parent
            link="RL_calf" />
        <child
            link="RL_foot" />
        <axis
            xyz="0 0 0" />
    </joint>
    <link
        name="RR_hip">
        <inertial>
            <origin
                xyz="0.0054 -0.00194 -0.000105"
                rpy="1.57079632 0 0" />
            <mass
                value="0.678" />
            <inertia
                ixx="0.00048"
                ixy="-3.01E-06"
                ixz="-1.11E-06"
                iyy="0.000884"
                iyz="1.42E-06"
                izz="0.000596" />
        </inertial>
        <visual>
            <origin
                xyz="0 0 0"
                rpy="4.712388 3.1415 0" />
            <geometry>
                <mesh
                    filename="../dae/hip.dae" />
            </geometry>
            <material
                name="">
                <color
                    rgba="1 1 1 1" />
            </material>
        </visual>
        <!-- <collision>
            <origin rpy="3.141592 0 0" xyz="0 -0.08 0" />
            <geometry>
                <cylinder length="0.04" radius="0.046" />
            </geometry>
        </collision> -->
    </link>
    <joint
        name="RR_hip_joint"
        type="revolute">
        <origin
            xyz="-0.1934 -0.0465 0"
            rpy="0 0 0" />
        <parent
            link="base" />
        <child
            link="RR_hip" />
        <axis
            xyz="1 0 0" />
        <limit
            lower="-1.0472"
            upper="1.0472"
            effort="23.7"
            velocity="30.1" />
    </joint>
    <link
        name="RR_thigh">
        <inertial>
            <origin
                xyz="-0.00374 0.0223 -0.0327"
                rpy="1.57079632 0 0" />
            <mass
                value="1.152" />
            <inertia
                ixx="0.00584"
                ixy="-8.72E-05"
                ixz="-0.000289"
                iyy="0.0058"
                iyz="-0.000808"
                izz="0.00103" />
        </inertial>
        <visual>
            <origin
                xyz="0 0 0"
                rpy="1.57079632 0 0" />
            <geometry>
                <mesh
                    filename="../dae/thigh_mirror.dae" />
            </geometry>
            <material
                name="">
                <color
                    rgba="1 1 1 1" />
            </material>
        </visual>
        <collision>
            <origin rpy="1.57079632 1.5707963267948966 0" xyz="0 0 -0.1065" />
            <geometry>
                <box size="0.213 0.0245 0.034" />
            </geometry>
        </collision>
    </link>
    <joint
        name="RR_thigh_joint"
        type="revolute">
        <origin
            xyz="0 -0.0955 0"
            rpy="0 0 0" />
        <parent
            link="RR_hip" />
        <child
            link="RR_thigh" />
        <axis
            xyz="0 1 0" />
        <limit
            lower="-0.5236"
            upper="4.5379"
            effort="23.7"
            velocity="30.1" />
    </joint>
    <link
        name="RR_calf">
        <inertial>
            <origin
                xyz="0.00548 0.000975 -0.115"
                rpy="1.57079632 0 0" />
            <mass
                value="0.154" />
            <inertia
                ixx="0.00108"
                ixy="-3.4E-07"
                ixz="1.72E-05"
                iyy="0.0011"
                iyz="-8.28E-06"
                izz="3.29E-05" />
        </inertial>
        <visual>
            <origin
                xyz="0 0 0"
                rpy="1.57079632 0 0" />
            <geometry>
                <mesh
                    filename="../dae/calf_mirror.dae" />
            </geometry>
            <material
                name="">
                <color
                    rgba="1 1 1 1" />
            </material>
        </visual>
        <collision>
            <origin rpy="1.57079632 -0.2 0" xyz="0.01 0 -0.06" />
            <geometry>
                <cylinder length="0.12" radius="0.013" />
            </geometry>
        </collision>
    </link>
    <joint
        name="RR_calf_joint"
        type="revolute">
        <origin
            xyz="0 0 -0.213"
            rpy="0 0 0" />
        <parent
            link="RR_thigh" />
        <child
            link="RR_calf" />
        <axis
            xyz="0 1 0" />
        <limit
            lower="-2.7227"
            upper="-0.83776"
            effort="45.43"
            velocity="15.70" />
    </joint>
    <link
        name="RR_calflower">
        <collision>
            <origin rpy="1.57079632 0 0" xyz="0 0 0" />
            <geometry>
                <cylinder length="0.065" radius="0.011" />
            </geometry>
        </collision>
    </link>
    <joint
        name="RR_calflower_joint"
        type="fixed">
        <origin
            xyz="0.020 0 -0.148"
            rpy="0 0.05 0" />
        <parent
            link="RR_calf" />
        <child
            link="RR_calflower" />
        <axis
            xyz="0 0 0" />
    </joint>
    <link
        name="RR_calflower1">
        <collision>
            <origin rpy="1.57079632 0 0" xyz="0 0 0" />
            <geometry>
                <cylinder length="0.03" radius="0.0155" />
            </geometry>
        </collision>
    </link>
    <joint
        name="RR_calflower1_joint"
        type="fixed">
        <origin
            xyz="-0.01 0 -0.04"
            rpy="0 0.48 0" />
        <parent
            link="RR_calflower" />
        <child
            link="RR_calflower1" />
        <axis
            xyz="0 0 0" />
    </joint>
    <link
        name="RR_foot">
        <inertial>
            <origin
                xyz="0 0 0"
                rpy="1.57079632 0 0" />
            <mass
                value="0.04" />
            <inertia
                ixx="9.6e-06"
                ixy="0"
                ixz="0"
                iyy="9.6e-06"
                iyz="0"
                izz="9.6e-06" />
        </inertial>
        <visual>
            <origin
                xyz="0 0 0"
                rpy="1.57079632 0 0" />
            <geometry>
                <mesh
                    filename="../dae/foot.dae" />
            </geometry>
            <material
                name="">
                <color
                    rgba="1 1 1 1" />
            </material>
        </visual>
        <collision>
            <origin rpy="1.57079632 0 0" xyz="-0.002 0 0" />
            <geometry>
                <sphere radius="0.022" />
            </geometry>
        </collision>
    </link>
    <joint
        name="RR_foot_joint"
        type="fixed" dont_collapse="true">
        <origin
            xyz="0 0 -0.213"
            rpy="0 0 0" />
        <parent
            link="RR_calf" />
        <child
            link="RR_foot" />
        <axis
            xyz="0 0 0" />
    </joint>
    <link
        name="imu">
        <inertial>
            <origin
                xyz="0 0 0"
                rpy="1.57079632 0 0" />
            <mass
                value="0" />
            <inertia
                ixx="0"
                ixy="0"
                ixz="0"
                iyy="0"
                iyz="0"
                izz="0" />
        </inertial>
    </link>
    <joint
        name="imu_joint"
        type="fixed">
        <origin
            xyz="-0.02557 0 0.04232"
            rpy="0 0 0" />
        <parent
            link="base" />
        <child
            link="imu" />
        <axis
            xyz="0 0 0" />
    </joint>
    <link
        name="radar">
        <inertial>
            <origin
                xyz="0 0 0"
                rpy="1.57079632 0 0" />
            <mass
                value="0" />
            <inertia
                ixx="0"
                ixy="0"
                ixz="0"
                iyy="0"
                iyz="0"
                izz="0" />
        </inertial>
    </link>
    <joint
        name="radar_joint"
        type="fixed">
        <origin
            xyz="0.28945 0 -0.046825"
            rpy="0 2.8782 0" />
        <parent
            link="base" />
        <child
            link="radar" />
        <axis
            xyz="0 0 0" />
    </joint>


    <!-- widow x config -->
    <joint name="widow_mount" type="fixed">
        <origin rpy="0 0 0" xyz="0.03 0 0.057" />
        <parent link="base" />
        <child link="wx250s/base_link" />
    </joint>
    <link name="wx250s/base_link">
        <visual>
            <origin rpy="0 0 1.5707963267948966" xyz="0 0 0" />
            <geometry>
                <mesh filename="../../widowGo1/meshes/wx250s_meshes/wx250s_1_base.stl" scale="0.001 0.001 0.001" />
            </geometry>
            <material name="black" />
        </visual>
        <collision>
            <origin rpy="0 0 1.5707963267948966" xyz="0 0 0" />
            <geometry>
                <mesh filename="../../widowGo1/meshes/wx250s_meshes/wx250s_1_base.stl" scale="0.001 0.001 0.001" />
            </geometry>
        </collision>
        <inertial>
            <origin rpy="0 0 1.5707963267948966" xyz="-0.0380446000 0.0006138920 0.0193354000" />
            <mass value="0.538736" />
            <inertia ixx="0.0021150000" ixy="-0.0000163500" ixz="0.0000006998" iyy="0.0006921000"
                iyz="0.0000464200" izz="0.0025240000" />
        </inertial>
    </link>
    <joint name="widow_waist" type="revolute">
        <axis xyz="0 0 1" />
        <limit effort="10" lower="-3.141582653589793" upper="3.141582653589793"
            velocity="3.141592653589793" />
        <!-- <limit effort="10" velocity="3.141592653589793"/> -->
        <origin rpy="0 0 0" xyz="0 0 0.072" />
        <parent link="wx250s/base_link" />
        <child link="wx250s/shoulder_link" />
        <dynamics friction="0" />
    </joint>

    <link name="wx250s/shoulder_link">
        <visual>
            <origin rpy="0 0 1.5707963267948966" xyz="0 0 -0.003" />
            <geometry>
                <mesh filename="../../widowGo1/meshes/wx250s_meshes/wx250s_2_shoulder.stl"
                    scale="0.001 0.001 0.001" />
            </geometry>
            <material name="black" />
        </visual>
        <collision>
            <origin rpy="0 0 1.5707963267948966" xyz="0 0 -0.003" />
            <geometry>
                <mesh filename="../../widowGo1/meshes/wx250s_meshes/wx250s_2_shoulder.stl"
                    scale="0.001 0.001 0.001" />
            </geometry>
        </collision>
        <inertial>
            <origin rpy="0 0 1.5707963267948966" xyz="0.0000223482 0.0000414609 0.0066287000" />
            <mass value="0.480879" />
            <inertia ixx="0.0003790000" ixy="0.0000000022" ixz="-0.0000003561" iyy="0.0005557000"
                iyz="0.0000012245" izz="0.0005889000" />
        </inertial>
    </link>
    <joint name="widow_shoulder" type="revolute">
        <axis xyz="0 1 0" />
        <limit effort="20" lower="-1.8849555921538759" upper="1.9896753472735358"
            velocity="3.141592653589793" />
        <origin rpy="0 0 0" xyz="0 0 0.03865" />
        <parent link="wx250s/shoulder_link" />
        <child link="wx250s/upper_arm_link" />
        <dynamics friction="0" />
    </joint>

    <link name="wx250s/upper_arm_link">
        <visual>
            <origin rpy="0 0 1.5707963267948966" xyz="0 0 0" />
            <geometry>
                <mesh filename="../../widowGo1/meshes/wx250s_meshes/wx250s_3_upper_arm.stl"
                    scale="0.001 0.001 0.001" />
            </geometry>
            <material name="black" />
        </visual>
        <collision>
            <origin rpy="0 0 1.5707963267948966" xyz="0 0 0" />
            <geometry>
                <mesh filename="../../widowGo1/meshes/wx250s_meshes/wx250s_3_upper_arm.stl"
                    scale="0.001 0.001 0.001" />
            </geometry>
        </collision>
        <inertial>
            <origin rpy="0 0 1.5707963267948966" xyz="0.0171605000 0.0000002725 0.1913230000" />
            <mass value="0.430811" />
            <inertia ixx="0.0034630000" ixy="-0.0000000001" ixz="-0.0000000002" iyy="0.0035870000"
                iyz="0.0004272000" izz="0.0004566000" />
        </inertial>
    </link>
    <joint name="widow_elbow" type="revolute">
        <axis xyz="0 1 0" />
        <limit effort="15" lower="-2.1467549799530254" upper="1.6057029118347832"
            velocity="3.141592653589793" />
        <origin rpy="0 0 0" xyz="0.04975 0 0.25" />
        <parent link="wx250s/upper_arm_link" />
        <child link="wx250s/upper_forearm_link" />
        <dynamics friction="0" />
    </joint>

    <link name="wx250s/upper_forearm_link">
        <visual>
            <origin rpy="0 0 0" xyz="0 0 0" />
            <geometry>
                <mesh filename="../../widowGo1/meshes/wx250s_meshes/wx250s_4_upper_forearm.stl"
                    scale="0.001 0.001 0.001" />
            </geometry>
            <material name="black" />
        </visual>
        <collision>
            <origin rpy="0 0 0" xyz="0 0 0" />
            <geometry>
                <mesh filename="../../widowGo1/meshes/wx250s_meshes/wx250s_4_upper_forearm.stl"
                    scale="0.001 0.001 0.001" />
            </geometry>
        </collision>
        <inertial>
            <origin rpy="0 0 0" xyz="0.1079630000 0.0001158760 0" />
            <mass value="0.234589" />
            <inertia ixx="0.0000397100" ixy="0.0000023528" ixz="0" iyy="0.0008878000" iyz="0"
                izz="0.0008880000" />
        </inertial>
    </link>
    <joint name="widow_forearm_roll" type="revolute">
        <axis xyz="1 0 0" />
        <limit effort="2" lower="-3.141582653589793" upper="3.141582653589793"
            velocity="3.141592653589793" />
        <origin rpy="0 0 0" xyz="0.175 0 0" />
        <parent link="wx250s/upper_forearm_link" />
        <child link="wx250s/lower_forearm_link" />
        <dynamics friction="0" />
    </joint>

    <link name="wx250s/lower_forearm_link">
        <visual>
            <origin rpy="3.141592653589793 0 0" xyz="0 0 0" />
            <geometry>
                <mesh filename="../../widowGo1/meshes/wx250s_meshes/wx250s_5_lower_forearm.stl"
                    scale="0.001 0.001 0.001" />
            </geometry>
            <material name="black" />
        </visual>
        <collision>
            <origin rpy="3.141592653589793 0 0" xyz="0 0 0" />
            <geometry>
                <mesh filename="../../widowGo1/meshes/wx250s_meshes/wx250s_5_lower_forearm.stl"
                    scale="0.001 0.001 0.001" />
            </geometry>
        </collision>
        <inertial>
            <origin rpy="3.141592653589793 0 0" xyz="0.0374395000 0.0052225200 0" />
            <mass value="0.220991" />
            <inertia ixx="0.0000636900" ixy="-0.0000229200" ixz="0" iyy="0.0001677000" iyz="0"
                izz="0.0001834000" />
        </inertial>
    </link>
    <joint name="widow_wrist_angle" type="revolute">
        <axis xyz="0 1 0" />
        <limit effort="5" lower="-1.7453292519943295" upper="2.1467549799530254"
            velocity="3.141592653589793" />
        <origin rpy="0 0 0" xyz="0.075 0 0" />
        <parent link="wx250s/lower_forearm_link" />
        <child link="wx250s/wrist_link" />
        <dynamics friction="0" />
    </joint>

    <link name="wx250s/wrist_link">
        <visual>
            <origin rpy="0 0 1.5707963267948966" xyz="0 0 0" />
            <geometry>
                <mesh filename="../../widowGo1/meshes/wx250s_meshes/wx250s_6_wrist.stl"
                    scale="0.001 0.001 0.001" />
            </geometry>
            <material name="black" />
        </visual>
        <collision>
            <origin rpy="0 0 1.5707963267948966" xyz="0 0 0" />
            <geometry>
                <mesh filename="../../widowGo1/meshes/wx250s_meshes/wx250s_6_wrist.stl"
                    scale="0.001 0.001 0.001" />
            </geometry>
        </collision>
        <inertial>
            <origin rpy="0 0 1.5707963267948966" xyz="0.0423600000 -0.0000106630 0.0105770000" />
            <mass value="0.084957" />
            <inertia ixx="0.0000308200" ixy="0.0000000191" ixz="0.0000000023" iyy="0.0000282200"
                iyz="0.0000025481" izz="0.0000315200" />
        </inertial>
    </link>
    <joint name="widow_wrist_rotate" type="revolute">
        <axis xyz="1 0 0" />
        <limit effort="1" lower="-3.141582653589793" upper="3.141582653589793"
            velocity="3.141592653589793" />
        <origin rpy="0 0 0" xyz="0.065 0 0" />
        <parent link="wx250s/wrist_link" />
        <child link="wx250s/gripper_link" />
        <dynamics friction="0" />
    </joint>

    <link name="wx250s/gripper_link">
        <visual>
            <origin rpy="0 0 1.5707963267948966" xyz="-0.02 0 0" />
            <geometry>
                <mesh filename="../../widowGo1/meshes/wx250s_meshes/wx250s_7_gripper.stl"
                    scale="0.001 0.001 0.001" />
            </geometry>
            <material name="black" />
        </visual>
        <collision>
            <origin rpy="0 0 1.5707963267948966" xyz="-0.02 0 0" />
            <geometry>
                <mesh filename="../../widowGo1/meshes/wx250s_meshes/wx250s_7_gripper.stl"
                    scale="0.001 0.001 0.001" />
            </geometry>
        </collision>
        <inertial>
            <origin rpy="0 0 1.5707963267948966" xyz="0.0216310000 0.0000002516 0.0114100000" />
            <mass value="0.072885" />
            <inertia ixx="0.0000253700" ixy="0.0000000000" ixz="0.0000000000" iyy="0.0000183600"
                iyz="0.0000004340" izz="0.0000167400" />
        </inertial>
    </link>
    <joint name="ee_arm" type="fixed">
        <axis xyz="1 0 0" />
        <origin rpy="0 0 0" xyz="0.043 0 0" />
        <parent link="wx250s/gripper_link" />
        <child link="wx250s/ee_arm_link" />
    </joint>
    <link name="wx250s/ee_arm_link">
        <inertial>
            <mass value="0.001" />
            <inertia ixx="0.001" ixy="0" ixz="0" iyy="0.001" iyz="0" izz="0.001" />
        </inertial>
    </link>
    <joint name="gripper" type="fixed">
        <axis xyz="1 0 0" />
        <limit effort="1" velocity="3.141592653589793" />
        <origin rpy="0 0 0" xyz="0.0055 0 0" />
        <parent link="wx250s/ee_arm_link" />
        <child link="wx250s/gripper_prop_link" />
        <dynamics friction="0" />
    </joint>

    <link name="wx250s/gripper_prop_link">
        <visual>
            <origin rpy="0 0 1.5707963267948966" xyz="-0.0685 0 0" />
            <geometry>
                <mesh filename="../../widowGo1/meshes/wx250s_meshes/wx250s_8_gripper_prop.stl"
                    scale="0.001 0.001 0.001" />
            </geometry>
            <material name="black" />
        </visual>
        <collision>
            <origin rpy="0 0 1.5707963267948966" xyz="-0.0685 0 0" />
            <geometry>
                <mesh filename="../../widowGo1/meshes/wx250s_meshes/wx250s_8_gripper_prop.stl"
                    scale="0.001 0.001 0.001" />
            </geometry>
        </collision>
        <inertial>
            <origin rpy="0 0 1.5707963267948966" xyz="0.0008460000 -0.0000016817 0.0000420000" />
            <mass value="0.00434" />
            <inertia ixx="0.0000005923" ixy="0.0000000000" ixz="0.0000003195" iyy="0.0000011156"
                iyz="-0.0000000004" izz="0.0000005743" />
        </inertial>
    </link>
    <!-- If the AR tag is being used, then add the AR tag mount -->
    <!-- If the gripper bar is being used, then also add the gripper bar -->
    <joint name="gripper_bar" type="fixed">
        <axis xyz="1 0 0" />
        <origin rpy="0 0 0" xyz="0 0 0" />
        <parent link="wx250s/ee_arm_link" />
        <child link="wx250s/gripper_bar_link" />
    </joint>
    <link name="wx250s/gripper_bar_link">
        <visual>
            <origin rpy="0 0 1.5707963267948966" xyz="-0.063 0 0" />
            <geometry>
                <mesh filename="../../widowGo1/meshes/wx250s_meshes/wx250s_9_gripper_bar.stl"
                    scale="0.001 0.001 0.001" />
            </geometry>
            <material name="black" />
        </visual>
        <collision>
            <origin rpy="0 0 1.5707963267948966" xyz="-0.063 0 0" />
            <geometry>
                <mesh filename="../../widowGo1/meshes/wx250s_meshes/wx250s_9_gripper_bar.stl"
                    scale="0.001 0.001 0.001" />
            </geometry>
        </collision>
        <inertial>
            <origin rpy="0 0 1.5707963267948966" xyz="0.0096870000 0.0000008177 0.0049620000" />
            <mass value="0.034199" />
            <inertia ixx="0.0000074125" ixy="-0.0000000008" ixz="-0.0000000006" iyy="0.0000284300"
                iyz="-0.0000013889" izz="0.0000286000" />
        </inertial>
    </link>
    <joint name="ee_bar" type="fixed">
        <axis xyz="1 0 0" />
        <origin rpy="0 0 0" xyz="0.023 0 0" />
        <parent link="wx250s/gripper_bar_link" />
        <child link="wx250s/fingers_link" />
    </joint>
    <link name="wx250s/fingers_link">
        <inertial>
            <mass value="0.001" />
            <inertia ixx="0.001" ixy="0" ixz="0" iyy="0.001" iyz="0" izz="0.001" />
        </inertial>
    </link>
    <!-- If the gripper fingers are being used, add those as well -->
    <joint name="widow_left_finger" type="prismatic">
        <axis xyz="0 1 0" />
        <limit effort="5" lower="0.015" upper="0.037" velocity="1" />
        <origin rpy="0 0 0" xyz="0 0 0" />
        <parent link="wx250s/fingers_link" />
        <child link="wx250s/left_finger_link" />
        <dynamics friction="1000" />
    </joint>

    <link name="wx250s/left_finger_link">
        <visual>
            <origin rpy="3.141592653589793 3.141592653589793 0" xyz="0 0.005 0" />
            <geometry>
                <mesh filename="../../widowGo1/meshes/wx250s_meshes/wx250s_10_gripper_finger.stl"
                    scale="0.001 0.001 0.001" />
            </geometry>
            <material name="black" />
        </visual>
        <collision>
            <origin rpy="3.141592653589793 3.141592653589793 0" xyz="0 0.005 0" />
            <geometry>
                <mesh filename="../../widowGo1/meshes/wx250s_meshes/wx250s_10_gripper_finger.stl"
                    scale="0.001 0.001 0.001" />
            </geometry>
        </collision>
        <inertial>
            <origin rpy="3.141592653589793 3.141592653589793 1.5707963267948966"
                xyz="0.0138160000 0.0000000000 0.0000000000" />
            <mass value="0.016246" />
            <inertia ixx="0.0000047310" ixy="-0.0000004560" ixz="0.0000000000" iyy="0.0000015506"
                iyz="0.0000000000" izz="0.0000037467" />
        </inertial>
    </link>
    <joint name="widow_right_finger" type="prismatic">
        <axis xyz="0 1 0" />
        <limit effort="5" lower="-0.037" upper="-0.015" velocity="1" />
        <origin rpy="0 0 0" xyz="0 0 0" />
        <parent link="wx250s/fingers_link" />
        <child link="wx250s/right_finger_link" />
        <dynamics friction="1000" />
        <mimic joint="widow_left_finger" multiplier="-1" offset="0" />
    </joint>

    <link name="wx250s/right_finger_link">
        <visual>
            <origin rpy="0 3.141592653589793 0" xyz="0 -0.005 0" />
            <geometry>
                <mesh filename="../../widowGo1/meshes/wx250s_meshes/wx250s_10_gripper_finger.stl"
                    scale="0.001 0.001 0.001" />
            </geometry>
            <material name="black" />
        </visual>
        <collision>
            <origin rpy="0 3.141592653589793 0" xyz="0 -0.005 0" />
            <geometry>
                <mesh filename="../../widowGo1/meshes/wx250s_meshes/wx250s_10_gripper_finger.stl"
                    scale="0.001 0.001 0.001" />
            </geometry>
        </collision>
        <inertial>
            <origin rpy="0 3.141592653589793 1.5707963267948966"
                xyz="0.0138160000 0.0000000000  0.0000000000" />
            <mass value="0.016246" />
            <inertia ixx="0.0000047310" ixy="0.0000004560" ixz="0.0000000000" iyy="0.0000015506"
                iyz="0.0000000000" izz="0.0000037467" />
        </inertial>
    </link>
    <joint name="ee_gripper" type="fixed" dont_collapse="true">
        <axis xyz="1 0 0" />
        <origin rpy="0 0 0" xyz="0.027575 0 0" />
        <parent link="wx250s/fingers_link" />
        <child link="wx250s/ee_gripper_link" />
    </joint>
    <link name="wx250s/ee_gripper_link">
        <inertial>
            <mass value="0.001" />
            <inertia ixx="0.001" ixy="0" ixz="0" iyy="0.001" iyz="0" izz="0.001" />
        </inertial>
    </link>
    <!-- widow x config ends -->

</robot>